Workbook

Sheet UPT-Weekday
A1: Route> | B1: 3 | C1: 4 | D1: 5 | E1: 6 | F1: 7 | G1: 8 | H1: 9 | I1: 14 | J1: 17 | K1: 18 | L1: 19 | M1: 21 | N1: 22 | O1: 23 | P1: 25 | Q1: 28 | R1: 29 | S1: 34 | T1: 41 | U1: 42 | V1: 50 | W1: 52 | X1: 55 | Y1: 56 | Z1: 64 | AA1: 70 | AB1: 71 | AC1: 72 | AD1: 75 | AE1: 76 | AF1: 77 | AG1: 79 | AH1: 84 | AI1: 86 | AJ1: 93 | AK1: 96 | AL1: 97 | AM1: AVERAGE
A2: Date
A3: 44197 | B3: 7116.78 | C3: 5952.43 | D3: 7457.63 | E3: 4138.55 | F3: 8590.56 | G3: 7615.01 | H3: 3382.43 | I3: 3617.2 | J3: 3664.93 | K3: 3245.1 | L3: 6578.85 | M3: 1308.74 | N3: 15175.21 | O3: 16259.46 | P3: 1641.25 | Q3: 2020.01 | R3: 6565.05 | S3: 1674.7 | U3: 2686.22 | V3: 17330.95 | W3: 24624.09 | X3: 33005.8 | Y3: 34691.39 | AC3: 498.72 | AE3: 3612.41 | AF3: 661.6 | AJ3: 1275 | AK3: 720 | AM3: =AVERAGE(B3:AL3) -> 8039.6454
A4: 44228 | B4: 7104 | C4: 4820 | D4: 6666 | E4: 3545 | F4: 8387 | G4: 6375 | H4: 2618 | I4: 2768 | J4: 3378 | K4: 2833 | L4: 5297 | M4: 972 | N4: 14033 | O4: 15803 | P4: 1568 | Q4: 1735 | R4: 4764 | S4: 1310 | T4: 0 | U4: 2297 | V4: 16603 | W4: 23670 | X4: 31763 | Y4: 32648 | Z4: 0 | AC4: 358 | AE4: 2934 | AF4: 547 | AH4: 0 | AI4: 0 | AJ4: 1180 | AK4: 647 | AM4: =AVERAGE(B4:AL4) -> 6456.9688
A5: 44256 | B5: 10033 | C5: 7887 | D5: 10666 | E5: 5856 | F5: 12154 | G5: 9648 | H5: 3476 | I5: 4319 | J5: 5285 | K5: 3775 | L5: 8652 | M5: 1562 | N5: 18474 | O5: 20924 | P5: 2422 | Q5: 2353 | R5: 7269 | S5: 2315 | T5: 0 | U5: 3280 | V5: 22461 | W5: 29896 | X5: 43926 | Y5: 45042 | Z5: 0 | AC5: 479 | AE5: 4535 | AF5: 725 | AH5: 0 | AI5: 0 | AJ5: 1602 | AK5: 914 | AM5: =AVERAGE(B5:AL5) -> 9060.3125
A6: 44287 | B6: 10558 | C6: 9303 | D6: 12008 | E6: 6623 | F6: 14896 | G6: 10023 | H6: 3860 | I6: 4458 | J6: 5797 | K6: 4480 | L6: 8857 | M6: 1496 | N6: 20127 | O6: 24513 | P6: 2084 | Q6: 2604 | R6: 7511 | S6: 2463 | T6: 215 | U6: 3492 | V6: 25108 | W6: 33270 | X6: 48466 | Y6: 46946 | Z6: 0 | AC6: 147 | AE6: 4979 | AF6: 1074 | AH6: 356 | AI6: 167 | AJ6: 1673 | AK6: 246 | AM6: =AVERAGE(B6:AL6) -> 9931.25
A7: 44317 | B7: 9648 | C7: 8465 | D7: 11046 | E7: 6243 | F7: 13984 | G7: 9148 | H7: 3353 | I7: 4041 | J7: 5207 | K7: 4266 | L7: 7576 | M7: 1162 | N7: 18298 | O7: 24712 | P7: 1523 | Q7: 2500 | R7: 6130 | S7: 2076 | T7: 292 | U7: 3312 | V7: 22083 | W7: 31695 | X7: 45554 | Y7: 42851 | Z7: 0 | AC7: 0 | AE7: 4926 | AF7: 1333 | AH7: 566 | AI7: 281 | AJ7: 1406 | AK7: 0 | AM7: =AVERAGE(B7:AL7) -> 9177.4062
A8: 44348 | B8: 10755 | C8: 9132 | D8: 11362 | E8: 6498 | F8: 15347 | G8: 10365 | H8: 4010 | I8: 4844 | J8: 6212 | K8: 5045 | L8: 9092 | M8: 1351 | N8: 19398 | O8: 26706 | P8: 1574 | Q8: 2806 | R8: 7064 | S8: 3218 | T8: 338 | U8: 3836 | V8: 23834 | W8: 35225 | X8: 53403 | Y8: 47727 | Z8: 0 | AC8: 0 | AE8: 5267 | AF8: 1817 | AH8: 766 | AI8: 405 | AJ8: 1651 | AK8: 0 | AM8: =AVERAGE(B8:AL8) -> 10282.75
A9: 44378 | B9: 10994 | C9: 9339 | D9: 11720 | E9: 6888 | F9: 15686 | G9: 10682 | H9: 3845 | I9: 4492 | J9: 6037 | K9: 5505 | L9: 9519 | M9: 1215 | N9: 19593 | O9: 27509 | P9: 1405 | Q9: 2913 | R9: 7266 | S9: 3630 | T9: 386 | U9: 3729 | V9: 24989 | W9: 37343 | X9: 59494 | Y9: 49155 | Z9: 0 | AC9: 0 | AE9: 5156 | AF9: 1857 | AH9: 815 | AI9: 475 | AJ9: 1646 | AK9: 0 | AM9: =AVERAGE(B9:AL9) -> 10727.594
A10: 44409 | B10: 13194 | C10: 11405 | D10: 15529 | E10: 8398 | F10: 21341 | G10: 12136 | H10: 4039 | I10: 4826 | J10: 6897 | K10: 6276 | L10: 11188 | M10: 1599 | N10: 20647 | O10: 30704 | P10: 2032 | Q10: 3318 | R10: 7555 | S10: 3471 | T10: 844 | U10: 3951 | V10: 28076 | W10: 40794 | X10: 67353 | Y10: 54630 | Z10: 0 | AC10: 0 | AE10: 5048 | AF10: 2091 | AH10: 1094 | AI10: 500 | AJ10: 2047 | AK10: 0 | AM10: =AVERAGE(B10:AL10) -> 12218.219
A11: 44440 | B11: 13757 | C11: 11450 | D11: 16904 | E11: 8751 | F11: 22891 | G11: 12271 | H11: 4158 | I11: 4959 | J11: 7442 | K11: 6059 | L11: 11996 | M11: 1667 | N11: 21047 | O11: 32895 | P11: 2268 | Q11: 3323 | R11: 7873 | S11: 3079 | T11: 1049 | U11: 4045 | V11: 30783 | W11: 41610 | X11: 70225 | Y11: 56263 | Z11: 10 | AC11: 0 | AE11: 5401 | AF11: 1940 | AH11: 1234 | AI11: 389 | AJ11: 1857 | AK11: 0 | AM11: =AVERAGE(B11:AL11) -> 12737.375
A12: 44470 | B12: 13937 | C12: 10989 | D12: 15858 | E12: 8298 | F12: 21632 | G12: 12185 | H12: 4749 | I12: 5104 | J12: 7350 | K12: 6401 | L12: 11580 | M12: 1580 | N12: 21495 | O12: 32202 | P12: 1952 | Q12: 3413 | R12: 7716 | S12: 3446 | T12: 959 | U12: 3799 | V12: 31349 | W12: 40857 | X12: 69184 | Y12: 53887 | Z12: 269 | AC12: 0 | AE12: 5541 | AF12: 2022 | AH12: 1304 | AI12: 567 | AJ12: 1790 | AK12: 0 | AL12: 9 | AM12: =AVERAGE(B12:AL12) -> 12164.364
A13: 44501 | B13: 13899 | C13: 11578 | D13: 15901 | E13: 8502 | F13: 21317 | G13: 12888 | H13: 5063 | I13: 5163 | J13: 6816 | K13: 6391 | L13: 12135 | M13: 1555 | N13: 22095 | O13: 32739 | P13: 1968 | Q13: 3447 | R13: 7625 | S13: 3427 | T13: 1148 | U13: 3709 | V13: 32703 | W13: 39952 | X13: 71336 | Y13: 57231 | Z13: 107 | AC13: 0 | AE13: 5562 | AF13: 1843 | AH13: 1319 | AI13: 560 | AJ13: 2426 | AK13: 0 | AL13: 43 | AM13: =AVERAGE(B13:AL13) -> 12437.818
A14: 44531 | B14: 13077 | C14: 10813 | D14: 14275 | E14: 7860 | F14: 19145 | G14: 14585 | H14: 5059 | I14: 5279 | J14: 6904 | K14: 6198 | L14: 10713 | M14: 1266 | N14: 21606 | O14: 32083 | P14: 1612 | Q14: 3338 | R14: 7463 | S14: 4095 | T14: 858 | U14: 3922 | V14: 31933 | W14: 40676 | X14: 70145 | Y14: 56589 | Z14: 121 | AC14: 0 | AE14: 5793 | AF14: 1929 | AH14: 1075 | AI14: 577 | AJ14: 1615 | AK14: 0 | AL14: 47 | AM14: =AVERAGE(B14:AL14) -> 12140.939
A15: 44562 | B15: 11911 | C15: 10063 | D15: 13105 | E15: 7034 | F15: 18175 | G15: 12173 | H15: 4441 | I15: 4618 | J15: 6050 | K15: 5156 | L15: 9699 | M15: 1110 | N15: 19440 | O15: 32660 | P15: 1705 | Q15: 2964 | R15: 6470 | S15: 2699 | T15: 898 | U15: 3261 | V15: 28367 | W15: 34594 | X15: 59488 | Y15: 49928 | Z15: 67 | AC15: 0 | AE15: 4515 | AF15: 1661 | AH15: 1019 | AI15: 471 | AJ15: 1558 | AK15: 0 | AL15: 9 | AM15: =AVERAGE(B15:AL15) -> 10766.939
A16: 44593 | B16: 13091 | C16: 10583 | D16: 14612 | E16: 7141 | F16: 20088 | G16: 13489 | H16: 4839 | I16: 4857 | J16: 6643 | K16: 5422 | L16: 11127 | M16: 1355 | N16: 20320 | O16: 32766 | P16: 2185 | Q16: 2907 | R16: 6810 | S16: 2780 | T16: 1123 | U16: 3496 | V16: 29644 | W16: 37396 | X16: 63055 | Y16: 54474 | Z16: 130 | AC16: 0 | AE16: 5024 | AF16: 1911 | AH16: 1342 | AI16: 447 | AJ16: 2301 | AK16: 0 | AL16: 19 | AM16: =AVERAGE(B16:AL16) -> 11556.879
A17: 44621 | B17: 15494 | C17: 12138 | D17: 18542 | E17: 9972 | F17: 25207 | G17: 15535 | H17: 5718 | I17: 6095 | J17: 7730 | K17: 7761 | L17: 12886 | M17: 1611 | N17: 24347 | O17: 37299 | P17: 2376 | Q17: 3520 | R17: 8380 | S17: 4605 | T17: 1296 | U17: 4399 | V17: 35789 | W17: 48192 | X17: 80338 | Y17: 65253 | Z17: 249 | AC17: 0 | AE17: 5810 | AF17: 2227 | AH17: 1716 | AI17: 559 | AJ17: 2473 | AK17: 0 | AL17: 38 | AM17: =AVERAGE(B17:AL17) -> 14168.333
A18: 44652 | B18: 31739 | C18: 12358 | D18: 1382 | E18: 9543 | F18: 23615 | G18: 13461 | H18: 5774 | I18: 5995 | J18: 8799 | K18: 7431 | L18: 11511 | M18: 82 | N18: 22256 | O18: 34252 | P18: 76 | Q18: 3696 | R18: 7793 | S18: 4408 | T18: 1217 | U18: 4404 | V18: 33037 | W18: 45836 | X18: 75912 | Y18: 60139 | Z18: 235 | AC18: 0 | AD18: 1920 | AE18: 5036 | AF18: 3462 | AG18: 1069 | AH18: 1673 | AI18: 585 | AJ18: 2692 | AK18: 0 | AL18: 28 | AM18: =AVERAGE(B18:AL18) -> 12611.886
A19: 44682 | B19: 33732 | C19: 13059 | D19: 0 | E19: 10163 | F19: 23841 | G19: 14557 | H19: 5965 | I19: 5961 | J19: 8850 | K19: 7887 | L19: 12775 | M19: 0 | N19: 24312 | O19: 36798 | P19: 0 | Q19: 4349 | R19: 8428 | S19: 4728 | T19: 1059 | U19: 4768 | V19: 36832 | W19: 50829 | X19: 83894 | Y19: 64499 | Z19: 281 | AC19: 0 | AD19: 1747 | AE19: 5659 | AF19: 3663 | AG19: 2026 | AH19: 1779 | AI19: 516 | AJ19: 2448 | AK19: 0 | AL19: 41 | AM19: =AVERAGE(B19:AL19) -> 13584.171
A20: 44713 | B20: 32371 | C20: 11712 | D20: 0 | E20: 9675 | F20: 22689 | G20: 14686 | H20: 5853 | I20: 5484 | J20: 8552 | K20: 8595 | L20: 12346 | M20: 0 | N20: 22852 | O20: 34946 | P20: 0 | Q20: 4493 | R20: 9057 | S20: 5893 | T20: 766 | U20: 4569 | V20: 33092 | W20: 50170 | X20: 81565 | Y20: 59631 | Z20: 250 | AC20: 0 | AD20: 1707 | AE20: 5472 | AF20: 4127 | AG20: 2568 | AH20: 1807 | AI20: 499 | AJ20: 2197 | AK20: 0 | AL20: 25 | AM20: =AVERAGE(B20:AL20) -> 13075.686
A21: 44743 | B21: 32102 | C21: 11147 | D21: 0 | E21: 9430 | F21: 21978 | G21: 14364 | H21: 5784 | I21: 4823 | J21: 8171 | K21: 8241 | L21: 11914 | M21: 0 | N21: 22860 | O21: 33765 | P21: 0 | Q21: 3904 | R21: 8399 | S21: 5231 | T21: 657 | U21: 4341 | V21: 31095 | W21: 48649 | X21: 80342 | Y21: 56316 | Z21: 246 | AC21: 0 | AD21: 1391 | AE21: 4679 | AF21: 4062 | AG21: 2301 | AH21: 1621 | AI21: 508 | AJ21: 1987 | AK21: 0 | AL21: 34 | AM21: =AVERAGE(B21:AL21) -> 12581.2
A22: 44774 | B22: 43177 | C22: 16163 | D22: 0 | E22: 12909 | F22: 30036 | G22: 17969 | H22: 7511 | I22: 5840 | J22: 10870 | K22: 9637 | L22: 16320 | M22: 0 | N22: 28400 | O22: 43887 | P22: 0 | Q22: 5161 | R22: 10804 | S22: 5873 | T22: 1329 | U22: 5673 | V22: 43305 | W22: 58176 | X22: 99477 | Y22: 75453 | Z22: 270 | AC22: 0 | AD22: 2099 | AE22: 6042 | AF22: 5143 | AG22: 3321 | AH22: 2036 | AI22: 652 | AJ22: 2982 | AK22: 0 | AL22: 68 | AM22: =AVERAGE(B22:AL22) -> 16302.371
A23: 44805 | B23: 43540 | C23: 16047 | D23: 0 | E23: 13141 | F23: 30907 | G23: 16805 | H23: 7217 | I23: 6238 | J23: 11501 | K23: 9916 | L23: 16406 | M23: 0 | N23: 27126 | O23: 42574 | P23: 0 | Q23: 4987 | R23: 11407 | S23: 5240 | T23: 1209 | U23: 5482 | V23: 43727 | W23: 57352 | X23: 98176 | Y23: 75142 | Z23: 244 | AC23: 0 | AD23: 2643 | AE23: 6001 | AF23: 5235 | AG23: 3523 | AH23: 2115 | AI23: 557 | AJ23: 2887 | AK23: 0 | AL23: 60 | AM23: =AVERAGE(B23:AL23) -> 16211.571
A24: 44835 | B24: 40625 | C24: 14717 | D24: 0 | E24: 12209 | F24: 28863 | G24: 16545 | H24: 6799 | I24: 5666 | J24: 10825 | K24: 9542 | L24: 14643 | M24: 0 | N24: 24968 | O24: 41328 | P24: 0 | Q24: 5282 | R24: 10497 | S24: 5907 | T24: 1109 | U24: 4987 | V24: 39062 | W24: 54996 | X24: 90391 | Y24: 69446 | Z24: 311 | AC24: 0 | AD24: 2301 | AE24: 5700 | AF24: 4857 | AG24: 3211 | AH24: 2240 | AI24: 580 | AJ24: 2261 | AK24: 0 | AL24: 124 | AM24: =AVERAGE(B24:AL24) -> 15142.629
A25: 44866 | B25: 38973 | C25: 14141 | D25: 0 | E25: 11688 | F25: 26969 | G25: 16305 | H25: 6706 | I25: 5418 | J25: 10498 | K25: 8865 | L25: 14185 | M25: 0 | N25: 25032 | O25: 40146 | P25: 0 | Q25: 5189 | R25: 10198 | S25: 5696 | T25: 1090 | U25: 4948 | V25: 38838 | W25: 52142 | X25: 89788 | Y25: 69500 | Z25: 308 | AC25: 0 | AD25: 2046 | AE25: 5520 | AF25: 4649 | AG25: 3120 | AH25: 2124 | AI25: 649 | AJ25: 2320 | AK25: 0 | AL25: 221 | AM25: =AVERAGE(B25:AL25) -> 14779.2
A26: 44896 | B26: 32933 | C26: 12688 | D26: 0 | E26: 10352 | F26: 23523 | G26: 15998 | H26: 6475 | I26: 4806 | J26: 8644 | K26: 7701 | L26: 12335 | M26: 0 | N26: 23132 | O26: 38225 | P26: 0 | Q26: 4693 | R26: 8830 | S26: 6132 | T26: 980 | U26: 4583 | V26: 34808 | W26: 49604 | X26: 79093 | Y26: 63588 | Z26: 219 | AC26: 0 | AD26: 1230 | AE26: 5069 | AF26: 4102 | AG26: 2905 | AH26: 1665 | AI26: 396 | AJ26: 1816 | AK26: 0 | AL26: 229 | AM26: =AVERAGE(B26:AL26) -> 13335.829
A27: 44927 | B27: 34982 | C27: 12389 | E27: 11912 | F27: 25460 | G27: 15484 | H27: 6068 | I27: 4940 | J27: 9387 | K27: 7246 | L27: 13019 | N27: 23268 | O27: 37016 | Q27: 4622 | R27: 9389 | S27: 4460 | T27: 1044 | U27: 4400 | V27: 35454 | W27: 48858 | X27: 79931 | Y27: 64024 | Z27: 339 | AD27: 1694 | AE27: 4904 | AF27: 4123 | AG27: 3070 | AH27: 1966 | AI27: 544 | AJ27: 2247 | AM27: =AVERAGE(B27:AL27) -> 16284.138
A28: 44958 | B28: 36626 | C28: 13097 | E28: 12582 | F28: 26343 | G28: 16757 | H28: 6145 | I28: 5002 | J28: 9552 | K28: 7964 | L28: 14124 | N28: 23367 | O28: 39631 | Q28: 4647 | R28: 10325 | S28: 4324 | T28: 1072 | U28: 4412 | V28: 36406 | W28: 50956 | X28: 85143 | Y28: 68218 | Z28: 377 | AD28: 2011 | AE28: 4889 | AF28: 4324 | AG28: 3360 | AH28: 2135 | AI28: 522 | AJ28: 2203 | AM28: =AVERAGE(B28:AL28) -> 17121.172
A29: 44986 | B29: 41714 | C29: 15087 | E29: 14878 | F29: 28809 | G29: 19083 | H29: 7079 | I29: 5627 | J29: 10860 | K29: 9554 | L29: 16151 | N29: 26337 | O29: 46058 | Q29: 5029 | R29: 11794 | S29: 5558 | T29: 1130 | U29: 5844 | V29: 41480 | W29: 61533 | X29: 100529 | Y29: 77815 | Z29: 422 | AD29: 1940 | AE29: 5701 | AF29: 5066 | AG29: 3735 | AH29: 2330 | AI29: 599 | AJ29: 2551 | AM29: =AVERAGE(B29:AL29) -> 19803.207
A30: 45017 | B30: 39443 | C30: 13185 | E30: 12815 | F30: 26998 | G30: 16824 | H30: 6335 | I30: 5303 | J30: 10654 | K30: 8860 | L30: 14534 | N30: 23700 | O30: 41405 | Q30: 4480 | R30: 11014 | S30: 4929 | T30: 919 | U30: 5299 | V30: 39754 | W30: 56152 | X30: 88930 | Y30: 69096 | Z30: 348 | AD30: 1742 | AE30: 5347 | AF30: 5014 | AG30: 3742 | AH30: 2049 | AI30: 573 | AJ30: 2861 | AM30: =AVERAGE(B30:AL30) -> 18010.517
A31: 45047 | B31: 42334 | C31: 14166 | E31: 13793 | F31: 28722 | G31: 17905 | H31: 7084 | I31: 5515 | J31: 10897 | K31: 10356 | L31: 15875 | N31: 25724 | O31: 46758 | Q31: 5053 | R31: 11840 | S31: 5774 | T31: 914 | U31: 5813 | V31: 42785 | W31: 62180 | X31: 97818 | Y31: 77438 | Z31: 351 | AD31: 1477 | AE31: 5950 | AF31: 6097 | AG31: 4047 | AH31: 2008 | AI31: 678 | AJ31: 3010 | AM31: =AVERAGE(B31:AL31) -> 19736.621
A32: 45078 | B32: 37954 | C32: 13302 | E32: 12404 | F32: 28067 | G32: 16519 | H32: 7354 | I32: 5292 | J32: 10076 | K32: 9062 | L32: 14698 | N32: 24755 | O32: 44081 | Q32: 4490 | R32: 10472 | S32: 6113 | T32: 747 | U32: 5742 | V32: 37684 | W32: 60925 | X32: 95085 | Y32: 72239 | Z32: 296 | AD32: 1385 | AE32: 5778 | AF32: 6085 | AG32: 3835 | AH32: 1940 | AI32: 579 | AJ32: 2333 | AM32: =AVERAGE(B32:AL32) -> 18596.276
A33: 45108 | B33: 32131 | C33: 11749 | E33: 10932 | F33: 23089 | G33: 13877 | H33: 5984 | I33: 4551 | J33: 8519 | K33: 9028 | L33: 13373 | N33: 21649 | O33: 36553 | Q33: 3821 | R33: 8618 | S33: 5232 | T33: 595 | U33: 5126 | V33: 34433 | W33: 53104 | X33: 84652 | Y33: 63304 | Z33: 298 | AD33: 1301 | AE33: 5210 | AF33: 5153 | AG33: 3249 | AH33: 1792 | AI33: 451 | AJ33: 2281 | AM33: =AVERAGE(B33:AL33) -> 16208.793
A34: 45139 | B34: 42882 | C34: 16812 | E34: 14996 | F34: 30379 | G34: 16466 | H34: 7657 | I34: 5764 | J34: 12661 | K34: 11065 | L34: 18630 | N34: 26794 | O34: 49351 | Q34: 4609 | R34: 12930 | S34: 5535 | T34: 1088 | U34: 6600 | V34: 47793 | W34: 63599 | X34: 106922 | Y34: 81491 | Z34: 367 | AA34: 616 | AD34: 2077 | AE34: 6127 | AF34: 6479 | AG34: 4357 | AH34: 2266 | AI34: 996 | AJ34: 3326 | AM34: =AVERAGE(B34:AL34) -> 20354.5
A35: 45170 | B35: 43170 | C35: 16876 | E35: 14060 | F35: 30649 | G35: 15097 | H35: 7315 | I35: 5355 | J35: 11236 | K35: 9888 | L35: 18350 | N35: 25654 | O35: 45637 | Q35: 4341 | R35: 12453 | S35: 5357 | T35: 1030 | U35: 6072 | V35: 43878 | W35: 58870 | X35: 96135 | Y35: 74960 | Z35: 339 | AA35: 816 | AD35: 1876 | AE35: 5938 | AF35: 5881 | AG35: 4244 | AH35: 2709 | AI35: 1134 | AJ35: 2954 | AM35: =AVERAGE(B35:AL35) -> 19075.8
A36: 45200 | B36: 44299 | C36: 17105 | E36: 14949 | F36: 33060 | G36: 16077 | H36: 7714 | I36: 5893 | J36: 11607 | K36: 11323 | L36: 17708 | N36: 26879 | O36: 47701 | Q36: 4763 | R36: 12432 | S36: 5729 | T36: 1362 | U36: 6444 | V36: 45083 | W36: 61870 | X36: 100575 | Y36: 78963 | Z36: 202 | AA36: 933 | AD36: 2459 | AE36: 6031 | AF36: 5993 | AG36: 4654 | AH36: 2741 | AI36: 1036 | AJ36: 2670 | AM36: =AVERAGE(B36:AL36) -> 19941.833
A37: 45231 | B37: 40250 | C37: 16808 | E37: 15480 | F37: 30609 | G37: 16484 | H37: 7305 | I37: 5562 | J37: 11039 | K37: 9844 | L37: 16873 | N37: 25855 | O37: 46106 | Q37: 4892 | R37: 11727 | S37: 5670 | T37: 1299 | U37: 5691 | V37: 43285 | W37: 53892 | X37: 92392 | Y37: 77249 | Z37: 59 | AA37: 1032 | AD37: 1909 | AE37: 5955 | AF37: 5020 | AG37: 4603 | AH37: 2656 | AI37: 1157 | AJ37: 2676 | AM37: =AVERAGE(B37:AL37) -> 18779.3
A38: 45261 | B38: 34473 | C38: 14585 | E38: 13667 | F38: 26063 | G38: 17006 | H38: 6601 | I38: 5059 | J38: 9635 | K38: 8757 | L38: 14496 | N38: 23470 | O38: 43526 | Q38: 4177 | R38: 10016 | S38: 5909 | T38: 1116 | U38: 4823 | V38: 39141 | W38: 48485 | X38: 84755 | Y38: 68086 | Z38: 114 | AA38: 852 | AD38: 1497 | AE38: 5586 | AF38: 5586 | AG38: 4703 | AH38: 1956 | AI38: 768 | AJ38: 2007 | AM38: =AVERAGE(B38:AL38) -> 16897.167
A39: 45292 | B39: 31633 | C39: 13716 | E39: 12730 | F39: 25950 | G39: 16601 | H39: 6685 | I39: 4585 | J39: 9365 | K39: 8342 | L39: 12102 | N39: 23785 | O39: 40129 | Q39: 3647 | R39: 9837 | S39: 4463 | T39: 1105 | U39: 4958 | V39: 34481 | W39: 43401 | X39: 78929 | Y39: 64542 | Z39: 147 | AA39: 731 | AD39: 1652 | AE39: 4695 | AF39: 4695 | AG39: 3436 | AH39: 1876 | AI39: 823 | AJ39: 2279 | AM39: =AVERAGE(B39:AL39) -> 15710.667
A40: 45323 | B40: 41133 | C40: 17011 | E40: 15029 | F40: 32256 | G40: 19050 | H40: 7989 | I40: 5628 | J40: 12053 | K40: 9941 | L40: 16966 | N40: 30568 | O40: 48363 | Q40: 4790 | R40: 12832 | S40: 5532 | T40: 1394 | U40: 6374 | V40: 42450 | W40: 54914 | X40: 98435 | Y40: 81148 | Z40: 142 | AA40: 1328 | AD40: 2216 | AE40: 5699 | AF40: 5827 | AG40: 4522 | AH40: 2678 | AI40: 1213 | AJ40: 2804 | AM40: =AVERAGE(B40:AL40) -> 19676.167
...

Sheet UPT-SatSun
A1: Route> | B1: 3 | C1: 4 | D1: 5 | E1: 6 | F1: 7 | G1: 8 | H1: 9 | I1: 14 | J1: 17 | K1: 18 | L1: 19 | M1: 21 | N1: 22 | O1: 23 | P1: 25 | Q1: 28 | R1: 29 | S1: 34 | T1: 41 | U1: 42 | V1: 50 | W1: 52 | X1: 55 | Y1: 56 | Z1: 64 | AA1: 70 | AB1: 71 | AC1: 72 | AD1: 75 | AE1: 76 | AF1: 77 | AG1: 79 | AH1: 84 | AI1: 86 | AJ1: 93 | AK1: 96 | AL1: 97 | AM1: AVERAGE
A2: SAT/SUN COMBINED
A3: 44197 | B3: 2847.52 | C3: 2255.28 | D3: 2930.97 | E3: 827.51 | F3: 2857.81 | G3: 2536.3 | H3: 0 | I3: 1551.96 | J3: 983.4 | K3: 970.87 | L3: 2131.61 | M3: 233.67 | N3: 5641.21 | O3: 5925.41 | P3: 556.72 | Q3: 855.66 | R3: 2471.19 | S3: 1115.5 | U3: 1413.11 | V3: 6615.52 | W3: 10065.92 | X3: 12560.47 | Y3: 13914.45 | Z3: 0 | AB3: 0 | AC3: 113.62 | AD3: 0 | AE3: 836.83 | AF3: 155.85 | AG3: 0 | AH3: 0 | AJ3: 0 | AK3: 0 | AM3: 2496.0109
A4: 44228 | B4: 2147 | C4: 1438 | D4: 1513 | E4: 380 | F4: 2046 | G4: 1684 | H4: 0 | I4: 737 | J4: 877 | K4: 581 | L4: 1085 | M4: 147 | N4: 3572 | O4: 3820 | P4: 268 | Q4: 474 | R4: 1331 | S4: 630 | U4: 714 | V4: 4229 | W4: 6915 | X4: 8735 | Y4: 9130 | Z4: 0 | AB4: 0 | AC4: 65 | AD4: 0 | AE4: 485 | AF4: 77 | AG4: 0 | AH4: 0 | AJ4: 0 | AK4: 0 | AM4: 1608.4848
A5: 44256 | B5: 2262 | C5: 1672 | D5: 2287 | E5: 536 | F5: 2177 | G5: 1814 | H5: 0 | I5: 903 | J5: 914 | K5: 675 | L5: 1557 | M5: 203 | N5: 3950 | O5: 4338 | P5: 370 | Q5: 488 | R5: 1347 | S5: 1019 | U5: 970 | V5: 4595 | W5: 7372 | X5: 10180 | Y5: 9953 | Z5: 0 | AB5: 0 | AC5: 80 | AD5: 0 | AE5: 691 | AF5: 87 | AG5: 0 | AH5: 0 | AJ5: 0 | AK5: 0 | AM5: 1831.5152
A6: 44287 | B6: 2479 | C6: 1687 | D6: 2357 | E6: 826 | F6: 2500 | G6: 1913 | H6: 0 | I6: 1067 | J6: 1157 | K6: 889 | L6: 1786 | M6: 176 | N6: 4250 | O6: 4749 | P6: 217 | Q6: 569 | R6: 1447 | S6: 998 | U6: 1042 | V6: 5139 | W6: 8143 | X6: 11372 | Y6: 10098 | Z6: 0 | AB6: 0 | AC6: 41 | AD6: 0 | AE6: 500 | AF6: 119 | AG6: 0 | AH6: 0 | AJ6: 0 | AK6: 0 | AM6: 1985.4848
A7: 44317 | B7: 3010 | C7: 2103 | D7: 3134 | E7: 1274 | F7: 3353 | G7: 2350 | H7: 0 | I7: 1430 | J7: 1352 | K7: 1034 | L7: 2028 | M7: 134 | N7: 5303 | O7: 6900 | P7: 120 | Q7: 773 | R7: 1770 | S7: 1138 | U7: 1206 | V7: 5814 | W7: 10281 | X7: 15131 | Y7: 13122 | Z7: 0 | AB7: 0 | AC7: 0 | AD7: 0 | AE7: 1043 | AF7: 181 | AG7: 0 | AH7: 0 | AJ7: 0 | AK7: 0 | AM7: 2544.9697
A8: 44348 | B8: 2480 | C8: 1862 | D8: 2539 | E8: 1173 | F8: 3077 | G8: 2043 | H8: 0 | I8: 1112 | J8: 1300 | K8: 884 | L8: 1731 | M8: 125 | N8: 4475 | O8: 5907 | P8: 126 | Q8: 716 | R8: 1392 | S8: 1293 | U8: 960 | V8: 5455 | W8: 8913 | X8: 13198 | Y8: 11550 | Z8: 0 | AB8: 0 | AC8: 0 | AD8: 0 | AE8: 901 | AF8: 204 | AG8: 0 | AH8: 0 | AJ8: 0 | AK8: 0 | AM8: 2224.7273
A9: 44378 | B9: 2842 | C9: 2260 | D9: 3075 | E9: 1490 | F9: 3477 | G9: 2500 | H9: 0 | I9: 1148 | J9: 1402 | K9: 964 | L9: 2148 | M9: 150 | N9: 5022 | O9: 6878 | P9: 125 | Q9: 774 | R9: 1687 | S9: 1530 | U9: 1319 | V9: 6298 | W9: 10175 | X9: 17125 | Y9: 13220 | Z9: 0 | AB9: 0 | AC9: 0 | AD9: 0 | AE9: 998 | AF9: 300 | AG9: 0 | AH9: 0 | AJ9: 0 | AK9: 0 | AM9: 2633.5455
A10: 44409 | B10: 3073 | C10: 2181 | D10: 3200 | E10: 1347 | F10: 3900 | G10: 2625 | H10: 0 | I10: 1207 | J10: 1462 | K10: 1168 | L10: 2119 | M10: 136 | N10: 4683 | O10: 7020 | P10: 132 | Q10: 788 | R10: 1543 | S10: 1405 | U10: 1243 | V10: 5909 | W10: 10626 | X10: 16932 | Y10: 12902 | Z10: 0 | AB10: 0 | AC10: 0 | AD10: 0 | AE10: 983 | AF10: 257 | AG10: 0 | AH10: 0 | AJ10: 0 | AK10: 0 | AM10: 2631.5455
A11: 44440 | B11: 2994 | C11: 1684 | D11: 2913 | E11: 1192 | F11: 3993 | G11: 2312 | H11: 0 | I11: 990 | J11: 1403 | K11: 1106 | L11: 1901 | M11: 162 | N11: 4072 | O11: 6444 | P11: 142 | Q11: 640 | R11: 1527 | S11: 1156 | U11: 1197 | V11: 5876 | W11: 9469 | X11: 15209 | Y11: 11204 | Z11: 0 | AB11: 0 | AC11: 0 | AD11: 0 | AE11: 909 | AF11: 202 | AG11: 0 | AH11: 0 | AJ11: 0 | AK11: 0 | AM11: 2384.7576
A12: 44470 | B12: 3913 | C12: 2530 | D12: 4205 | E12: 1713 | F12: 4999 | G12: 3156 | H12: 0 | I12: 1580 | J12: 1934 | K12: 1429 | L12: 2725 | M12: 185 | N12: 5864 | O12: 8716 | P12: 177 | Q12: 922 | R12: 2071 | S12: 1762 | U12: 1540 | V12: 7868 | W12: 13054 | X12: 21715 | Y12: 15760 | Z12: 0 | AB12: 0 | AC12: 0 | AD12: 0 | AE12: 1329 | AF12: 247 | AG12: 0 | AH12: 0 | AJ12: 0 | AK12: 0 | AM12: 3314.9697
A13: 44501 | B13: 2917 | C13: 2117 | D13: 3046 | E13: 1316 | F13: 3570 | G13: 2573 | H13: 0 | I13: 1249 | J13: 1384 | K13: 1015 | L13: 2189 | M13: 179 | N13: 4336 | O13: 6640 | P13: 155 | Q13: 795 | R13: 1576 | S13: 1268 | U13: 1278 | V13: 6180 | W13: 9601 | X13: 16862 | Y13: 12210 | Z13: 0 | AB13: 0 | AC13: 0 | AD13: 0 | AE13: 1012 | AF13: 216 | AG13: 0 | AH13: 0 | AJ13: 0 | AK13: 0 | AM13: 2535.8788
A14: 44531 | B14: 2676 | C14: 2028 | D14: 2684 | E14: 1211 | F14: 3184 | G14: 2481 | H14: 0 | I14: 1159 | J14: 1194 | K14: 904 | L14: 1960 | M14: 116 | N14: 4042 | O14: 6019 | P14: 104 | Q14: 773 | R14: 1488 | S14: 1211 | U14: 1102 | V14: 5613 | W14: 8898 | X14: 15147 | Y14: 11428 | Z14: 0 | AB14: 0 | AC14: 0 | AD14: 0 | AE14: 988 | AF14: 163 | AG14: 0 | AH14: 0 | AJ14: 0 | AK14: 0 | AM14: 2320.3939
... A26: 44896 | B26: 8087 | C26: 2493 | D26: 0 | E26: 1983 | F26: 5063 | G26: 4007 | H26: 0 | I26: 1238 | J26: 1741 | K26: 1621 | L26: 2344 | M26: 0 | N26: 4838 | O26: 10009 | P26: 0 | Q26: 903 | R26: 1913 | S26: 1899 | U26: 1654 | V26: 7749 | W26: 12993 | X26: 21316 | Y26: 15211 | Z26: 0 | AB26: 0 | AC26: 0 | AD26: 115 | AE26: 1099 | AF26: 538 | AG26: 306 | AH26: 0 | AJ26: 0 | AK26: 0 | AM26: 3306.6667
A27: 44927 | B27: 6643 | C27: 2265 | E27: 1383 | F27: 4074 | G27: 3333 | H27: 0 | I27: 1532 | J27: 1587 | K27: 1125 | L27: 2413 | N27: 5326 | O27: 9796 | Q27: 1068 | R27: 1662 | S27: 1200 | U27: 1243 | V27: 6816 | W27: 10915 | X27: 18775 | Y27: 14680 | AD27: 148 | AE27: 1009 | AF27: 296 | AG27: 0 | AH27: 0 | AM27: 3891.56
A28: 44958 | B28: 6305 | C28: 2053 | E28: 1263 | F28: 3561 | G28: 2963 | H28: 0 | I28: 1250 | J28: 1450 | K28: 1006 | L28: 2159 | N28: 4426 | O28: 8273 | Q28: 680 | R28: 1540 | S28: 1118 | U28: 1209 | V28: 5910 | W28: 9722 | X28: 16682 | Y28: 13694 | AD28: 184 | AE28: 1048 | AF28: 354 | AG28: 0 | AH28: 0 | AM28: 3474
A29: 44986 | B29: 6656 | C29: 2224 | E29: 1297 | F29: 3913 | G29: 3004 | H29: 0 | I29: 1351 | J29: 1388 | K29: 1264 | L29: 2206 | N29: 4706 | O29: 7562 | Q29: 723 | R29: 1605 | S29: 1391 | U29: 1304 | V29: 6014 | W29: 10473 | X29: 18093 | Y29: 13527 | AD29: 153 | AE29: 938 | AF29: 383 | AG29: 0 | AH29: 0 | AM29: 3607
A30: 45017 | B30: 8174 | C30: 2500 | E30: 1861 | F30: 5143 | G30: 3535 | H30: 0 | I30: 1534 | J30: 1915 | K30: 1635 | L30: 2419 | N30: 6070 | O30: 9058 | Q30: 893 | R30: 2001 | S30: 1721 | U30: 1446 | V30: 8042 | W30: 13529 | X30: 22446 | Y30: 16796 | AD30: 166 | AE30: 1310 | AF30: 446 | AG30: 189 | AH30: 0 | AM30: 4513.16
A31: 45047 | B31: 9605 | C31: 2982 | E31: 2067 | F31: 5646 | G31: 4124 | H31: 0 | I31: 1593 | J31: 2048 | K31: 1980 | L31: 2880 | N31: 6126 | O31: 9739 | Q31: 1139 | R31: 2395 | S31: 1943 | U31: 1880 | V31: 9325 | W31: 16691 | X31: 26240 | Y31: 18143 | AD31: 113 | AE31: 1468 | AF31: 372 | AG31: 212 | AH31: 0 | AM31: 5148.44
A32: 45078 | B32: 8358 | C32: 2754 | E32: 1913 | F32: 5133 | G32: 3577 | H32: 0 | I32: 1122 | J32: 1831 | K32: 1762 | L32: 2684 | N32: 4956 | O32: 7995 | Q32: 1116 | R32: 2277 | S32: 2126 | U32: 1594 | V32: 7632 | W32: 13992 | X32: 23149 | Y32: 15111 | AD32: 150 | AE32: 1271 | AF32: 430 | AG32: 232 | AH32: 0 | AM32: 4446.6
A33: 45108 | B33: 11983 | C33: 3739 | E33: 2976 | F33: 8022 | G33: 4762 | H33: 0 | I33: 1701 | J33: 2374 | K33: 3603 | L33: 3793 | N33: 6462 | O33: 12802 | Q33: 1327 | R33: 3037 | S33: 2495 | U33: 2631 | V33: 12750 | W33: 20997 | X33: 32883 | Y33: 23477 | Z33: 0 | AB33: 0 | AD33: 113 | AE33: 1708 | AF33: 754 | AG33: 415 | AH33: 0 | AJ33: 0 | AK33: 0 | AM33: 5682.8966
A34: 45139 | B34: 8593 | C34: 2984 | E34: 2386 | F34: 5588 | G34: 3392 | H34: 0 | I34: 1100 | J34: 1835 | K34: 2954 | L34: 2809 | N34: 4907 | O34: 9833 | Q34: 941 | R34: 2200 | S34: 1732 | U34: 1867 | V34: 9652 | W34: 15433 | X34: 25020 | Y34: 16721 | Z34: 0 | AB34: 0 | AD34: 89 | AE34: 1234 | AF34: 614 | AG34: 316 | AH34: 0 | AJ34: 0 | AK34: 0 | AM34: 4213.7931
A35: 45170 | B35: 12856 | C35: 4428 | E35: 3133 | F35: 8472 | G35: 4355 | H35: 0 | I35: 1557 | J35: 2749 | K35: 4051 | L35: 4074 | N35: 6839 | O35: 13079 | Q35: 1442 | R35: 3146 | S35: 2657 | U35: 2605 | V35: 12466 | W35: 20879 | X35: 32100 | Y35: 22785 | Z35: 0 | AB35: 0 | AD35: 183 | AE35: 1793 | AF35: 1011 | AG35: 419 | AH35: 48 | AJ35: 0 | AK35: 0 | AM35: 5763
A36: 45200 | B36: 11074 | C36: 3598 | E36: 3051 | F36: 7455 | G36: 4700 | H36: 0 | I36: 1459 | J36: 2428 | K36: 3591 | L36: 3318 | N36: 6239 | O36: 11490 | Q36: 1296 | R36: 2772 | S36: 2319 | U36: 2415 | V36: 10861 | W36: 17860 | X36: 27671 | Y36: 19395 | Z36: 0 | AB36: 0 | AD36: 349 | AE36: 1610 | AF36: 1391 | AG36: 313 | AH36: 64 | AJ36: 0 | AK36: 0 | AM36: 5059.2759
A37: 45231 | B37: 9530 | C37: 3731 | E37: 2756 | F37: 6004 | G37: 4492 | H37: 0 | I37: 1403 | J37: 2041 | K37: 3091 | L37: 3203 | N37: 5633 | O37: 10349 | Q37: 1146 | R37: 2612 | S37: 2213 | U37: 2043 | V37: 10513 | W37: 15592 | X37: 25855 | Y37: 19060 | Z37: 0 | AB37: 0 | AD37: 288 | AE37: 1438 | AF37: 1189 | AG37: 291 | AH37: 0 | AJ37: 0 | AK37: 0 | AM37: 4637
A38: 45261 | B38: 11069 | C38: 4037 | E38: 3280 | F38: 7114 | G38: 6271 | H38: 0 | I38: 1676 | J38: 2429 | K38: 3538 | L38: 3766 | N38: 6546 | O38: 13352 | Q38: 1161 | R38: 2817 | S38: 2769 | U38: 2328 | V38: 11984 | W38: 17775 | X38: 29792 | Y38: 21915 | Z38: 933 | AB38: 0 | AD38: 395 | AE38: 1746 | AF38: 1354 | AG38: 376 | AH38: 0 | AJ38: 0 | AK38: 0 | AM38: 5462.8621
A39: 45292 | B39: 11612 | C39: 4121 | E39: 3624 | F39: 8090 | G39: 6894 | H39: 300 | I39: 1772 | J39: 2736 | K39: 3974 | L39: 2770 | N39: 7898 | O39: 15957 | Q39: 1371 | R39: 3388 | S39: 2440 | U39: 2566 | V39: 12203 | W39: 18660 | X39: 31255 | Y39: 23399 | Z39: 693 | AB39: 0 | AD39: 374 | AE39: 1672 | AF39: 1295 | AG39: 413 | AH39: 16 | AJ39: 86 | AM39: 6056.3929
A40: 45323 | B40: 9384 | C40: 3269 | E40: 2561 | F40: 6213 | G40: 5165 | H40: 0 | I40: 1302 | J40: 2048 | K40: 2834 | L40: 2860 | N40: 6324 | O40: 11277 | Q40: 1144 | R40: 2602 | S40: 2306 | U40: 2287 | V40: 8878 | W40: 14807 | X40: 24310 | Y40: 18283 | Z40: 0 | AB40: 0 | AD40: 340 | AE40: 1246 | AF40: 1234 | AG40: 322 | AH40: 50 | AJ40: 0 | AK40: 0 | AM40: 4518.8276
A41: 45352 | B41: 12149 | C41: 4063 | E41: 3578 | F41: 8081 | G41: 5902 | H41: 0 | I41: 1780 | J41: 2536 | K41: 3796 | L41: 3653 | N41: 7908 | O41: 12921 | Q41: 1139 | R41: 3353 | S41: 2579 | U41: 2930 | V41: 11744 | W41: 18988 | X41: 31863 | Y41: 22224 | Z41: 0 | AB41: 123 | AD41: 421 | AE41: 1666 | AF41: 1975 | AG41: 471 | AH41: 193 | AJ41: 0 | AK41: 0 | AM41: 5725.3793
A42: 45383 | B42: 9996 | C42: 3153 | E42: 3083 | F42: 6329 | G42: 3789 | H42: 0 | I42: 2491 | J42: 2199 | K42: 3202 | L42: 2776 | N42: 5452 | O42: 10070 | Q42: 580 | R42: 2551 | S42: 1794 | U42: 2277 | V42: 9661 | W42: 16279 | X42: 25474 | Y42: 17805 | Z42: 0 | AB42: 704 | AD42: 543 | AE42: 1310 | AF42: 1698 | AG42: 312 | AH42: 187 | AJ42: 0 | AK42: 0 | AM42: 4610.8621
A43: 45413 | B43: 11396 | C43: 3304 | E43: 3376 | F43: 6412 | G43: 4170 | H43: 0 | I43: 2612 | J43: 2328 | K43: 4396 | L43: 2992 | N43: 6399 | O43: 11415 | Q43: 674 | R43: 2807 | S43: 2246 | U43: 2695 | V43: 10656 | W43: 18509 | X43: 28018 | Y43: 20137 | Z43: 0 | AB43: 794 | AD43: 742 | AE43: 1553 | AF43: 2091 | AG43: 397 | AH43: 78 | AJ43: 0 | AK43: 0 | AM43: 5179.2069
A44: 45444 | B44: 12033 | C44: 3941 | E44: 3778 | F44: 7373 | G44: 4666 | H44: 0 | I44: 3147 | J44: 2705 | K44: 4472 | L44: 3347 | N44: 7195 | O44: 12939 | Q44: 745 | R44: 2918 | S44: 2352 | U44: 3492 | V44: 12017 | W44: 21394 | X44: 31122 | Y44: 21131 | Z44: 0 | AB44: 995 | AD44: 1046 | AE44: 1659 | AF44: 2392 | AG44: 415 | AH44: 190 | AJ44: 0 | AK44: 0 | AM44: 5774.6207
A45: 45474 | B45: 10613 | C45: 3614 | E45: 3200 | F45: 6405 | G45: 3976 | H45: 0 | I45: 2789 | J45: 2217 | K45: 3792 | L45: 2889 | N45: 5910 | O45: 11076 | Q45: 771 | R45: 2449 | S45: 2291 | U45: 2944 | V45: 10825 | W45: 17692 | X45: 26306 | Y45: 20061 | Z45: 0 | AB45: 873 | AD45: 931 | AE45: 1581 | AF45: 2107 | AG45: 363 | AH45: 0 | AJ45: 0 | AM45: 5202.6786
A46: 45505 | B46: 11505 | C46: 3933 | E46: 3654 | F46: 7130 | G46: 4453 | H46: 0 | I46: 2887 | J46: 2794 | K46: 4294 | L46: 3296 | N46: 6337 | O46: 11683 | Q46: 773 | R46: 2910 | S46: 2498 | U46: 2862 | V46: 12357 | W46: 19311 | X46: 28294 | Y46: 21507 | Z46: 0 | AB46: 1032 | AD46: 1158 | AE46: 1741 | AF46: 2416 | AG46: 490 | AH46: 52 | AJ46: 0 | AM46: 5691.6786
A47: 45536 | B47: 12663 | C47: 4368 | E47: 3939 | F47: 8153 | G47: 4664 | H47: 0 | I47: 3277 | J47: 3312 | K47: 4518 | L47: 3567 | N47: 7113 | O47: 12023 | Q47: 860 | R47: 3535 | S47: 2930 | U47: 3401 | V47: 13347 | W47: 19575 | X47: 29613 | Y47: 23909 | Z47: 0 | AB47: 1077 | AD47: 1697 | AE47: 1658 | AF47: 2744 | AG47: 351 | AH47: 45 | AJ47: 0 | AM47: 6154.9643
A48: 45566 | B48: 10767 | C48: 3868 | E48: 3470 | F48: 6793 | G48: 4178 | H48: 0 | I48: 2711 | J48: 2420 | K48: 3787 | L48: 3412 | N48: 6315 | O48: 11001 | Q48: 721 | R48: 2223 | S48: 2600 | U48: 2781 | V48: 10781 | W48: 16928 | X48: 24794 | Y48: 19979 | Z48: 0 | AB48: 918 | AD48: 1289 | AE48: 1441 | AF48: 2374 | AG48: 373 | AH48: 6 | AJ48: 0 | AM48: 5211.7857
A49: 45597 | B49: 11461 | C49: 4656 | E49: 3772 | F49: 7537 | G49: 5400 | H49: 0 | I49: 3478 | J49: 2735 | K49: 4103 | L49: 3444 | N49: 7287 | O49: 13401 | Q49: 780 | R49: 2995 | S49: 3136 | U49: 3116 | V49: 12560 | W49: 16953 | X49: 28541 | Y49: 23752 | Z49: 0 | AB49: 1432 | AD49: 1499 | AE49: 1964 | AF49: 2542 | AG49: 474 | AH49: 0 | AJ49: 0 | AM49: 5964.9286
A50: 45627 | B50: 9438 | C50: 4364 | E50: 3267 | F50: 6252 | G50: 5024 | H50: 0 | I50: 3249 | J50: 2279 | K50: 3423 | L50: 3107 | N50: 6972 | O50: 11956 | Q50: 671 | R50: 2201 | S50: 2786 | U50: 2129 | V50: 11382 | W50: 15241 | X50: 25924 | Y50: 23048 | Z50: 0 | AB50: 1324 | AD50: 1201 | AE50: 1837 | AF50: 2313 | AG50: 374 | AH50: 0 | AJ50: 0 | AM50: 5348.6429
A53: Date | B53: SATURDAY | F53: What about 2023 and 2024?
...

Sheet UPT- Total
A1: Route> | B1: 3 | C1: 4 | D1: 5 | E1: 6 | F1: 7 | G1: 8 | H1: 9 | I1: 14 | J1: 17 | K1: 18 | L1: 19 | M1: 21 | N1: 22 | O1: 23 | P1: 25 | Q1: 28 | R1: 29 | S1: 34 | T1: 41 | U1: 42 | V1: 50 | W1: 52 | X1: 55 | Y1: 56 | Z1: 64 | AA1: 70 | AB1: 71 | AC1: 72 | AD1: 75 | AE1: 76 | AF1: 77 | AG1: 79 | AH1: 84 | AI1: 86 | AJ1: 93 | AK1: 96 | AL1: 97 | AM1: AVERAGE
A2: Date
A3: 44197 | B3: ='UPT-Weekday'!B3+'UPT-SatSun'!B3 -> 9964.3 | C3: ='UPT-Weekday'!C3+'UPT-SatSun'!C3 -> 8207.71 | D3: ='UPT-Weekday'!D3+'UPT-SatSun'!D3 -> 10388.6 | E3: ='UPT-Weekday'!E3+'UPT-SatSun'!E3 -> 4966.06 | F3: ='UPT-Weekday'!F3+'UPT-SatSun'!F3 -> 11448.37 | G3: ='UPT-Weekday'!G3+'UPT-SatSun'!G3 -> 10151.31 | H3: ='UPT-Weekday'!H3+'UPT-SatSun'!H3 -> 3382.43 | I3: ='UPT-Weekday'!I3+'UPT-SatSun'!I3 -> 5169.16 | ... AL3: ='UPT-Weekday'!AL3+'UPT-SatSun'!AL3 -> 0 | AM3: =AVERAGE(B3:AL3) -> 8310.2278
A4: 44228 | B4: ='UPT-Weekday'!B4+'UPT-SatSun'!B4 -> 9251 | C4: ='UPT-Weekday'!C4+'UPT-SatSun'!C4 -> 6258 | D4: ='UPT-Weekday'!D4+'UPT-SatSun'!D4 -> 8179 | E4: ='UPT-Weekday'!E4+'UPT-SatSun'!E4 -> 3925 | F4: ='UPT-Weekday'!F4+'UPT-SatSun'!F4 -> 10433 | G4: ='UPT-Weekday'!G4+'UPT-SatSun'!G4 -> 8059 | H4: ='UPT-Weekday'!H4+'UPT-SatSun'!H4 -> 2618 | I4: ='UPT-Weekday'!I4+'UPT-SatSun'!I4 -> 3505 | ... AL4: ='UPT-Weekday'!AL4+'UPT-SatSun'!AL4 -> 0 | AM4: =AVERAGE(B4:AL4) -> 7019
A5: 44256 | B5: ='UPT-Weekday'!B5+'UPT-SatSun'!B5 -> 12295 | C5: ='UPT-Weekday'!C5+'UPT-SatSun'!C5 -> 9559 | D5: ='UPT-Weekday'!D5+'UPT-SatSun'!D5 -> 12953 | E5: ='UPT-Weekday'!E5+'UPT-SatSun'!E5 -> 6392 | F5: ='UPT-Weekday'!F5+'UPT-SatSun'!F5 -> 14331 | G5: ='UPT-Weekday'!G5+'UPT-SatSun'!G5 -> 11462 | H5: ='UPT-Weekday'!H5+'UPT-SatSun'!H5 -> 3476 | I5: ='UPT-Weekday'!I5+'UPT-SatSun'!I5 -> 5222 | ... AL5: ='UPT-Weekday'!AL5+'UPT-SatSun'!AL5 -> 0 | AM5: =AVERAGE(B5:AL5) -> 9469.4595
A6: 44287 | B6: ='UPT-Weekday'!B6+'UPT-SatSun'!B6 -> 13037 | C6: ='UPT-Weekday'!C6+'UPT-SatSun'!C6 -> 10990 | D6: ='UPT-Weekday'!D6+'UPT-SatSun'!D6 -> 14365 | E6: ='UPT-Weekday'!E6+'UPT-SatSun'!E6 -> 7449 | F6: ='UPT-Weekday'!F6+'UPT-SatSun'!F6 -> 17396 | G6: ='UPT-Weekday'!G6+'UPT-SatSun'!G6 -> 11936 | H6: ='UPT-Weekday'!H6+'UPT-SatSun'!H6 -> 3860 | I6: ='UPT-Weekday'!I6+'UPT-SatSun'!I6 -> 5525 | ... AL6: ='UPT-Weekday'!AL6+'UPT-SatSun'!AL6 -> 0 | AM6: =AVERAGE(B6:AL6) -> 10360.027
A7: 44317 | B7: ='UPT-Weekday'!B7+'UPT-SatSun'!B7 -> 12658 | C7: ='UPT-Weekday'!C7+'UPT-SatSun'!C7 -> 10568 | D7: ='UPT-Weekday'!D7+'UPT-SatSun'!D7 -> 14180 | E7: ='UPT-Weekday'!E7+'UPT-SatSun'!E7 -> 7517 | F7: ='UPT-Weekday'!F7+'UPT-SatSun'!F7 -> 17337 | G7: ='UPT-Weekday'!G7+'UPT-SatSun'!G7 -> 11498 | H7: ='UPT-Weekday'!H7+'UPT-SatSun'!H7 -> 3353 | I7: ='UPT-Weekday'!I7+'UPT-SatSun'!I7 -> 5471 | ... AL7: ='UPT-Weekday'!AL7+'UPT-SatSun'!AL7 -> 0 | AM7: =AVERAGE(B7:AL7) -> 10207.054
A8: 44348 | B8: ='UPT-Weekday'!B8+'UPT-SatSun'!B8 -> 13235 | C8: ='UPT-Weekday'!C8+'UPT-SatSun'!C8 -> 10994 | D8: ='UPT-Weekday'!D8+'UPT-SatSun'!D8 -> 13901 | E8: ='UPT-Weekday'!E8+'UPT-SatSun'!E8 -> 7671 | F8: ='UPT-Weekday'!F8+'UPT-SatSun'!F8 -> 18424 | G8: ='UPT-Weekday'!G8+'UPT-SatSun'!G8 -> 12408 | H8: ='UPT-Weekday'!H8+'UPT-SatSun'!H8 -> 4010 | I8: ='UPT-Weekday'!I8+'UPT-SatSun'!I8 -> 5956 | ... AL8: ='UPT-Weekday'!AL8+'UPT-SatSun'!AL8 -> 0 | AM8: =AVERAGE(B8:AL8) -> 10877.405
A9: 44378 | B9: ='UPT-Weekday'!B9+'UPT-SatSun'!B9 -> 13836 | C9: ='UPT-Weekday'!C9+'UPT-SatSun'!C9 -> 11599 | D9: ='UPT-Weekday'!D9+'UPT-SatSun'!D9 -> 14795 | E9: ='UPT-Weekday'!E9+'UPT-SatSun'!E9 -> 8378 | F9: ='UPT-Weekday'!F9+'UPT-SatSun'!F9 -> 19163 | G9: ='UPT-Weekday'!G9+'UPT-SatSun'!G9 -> 13182 | H9: ='UPT-Weekday'!H9+'UPT-SatSun'!H9 -> 3845 | I9: ='UPT-Weekday'!I9+'UPT-SatSun'!I9 -> 5640 | ... AL9: ='UPT-Weekday'!AL9+'UPT-SatSun'!AL9 -> 0 | AM9: =AVERAGE(B9:AL9) -> 11626.757
A10: 44409 | B10: ='UPT-Weekday'!B10+'UPT-SatSun'!B10 -> 16267 | C10: ='UPT-Weekday'!C10+'UPT-SatSun'!C10 -> 13586 | D10: ='UPT-Weekday'!D10+'UPT-SatSun'!D10 -> 18729 | E10: ='UPT-Weekday'!E10+'UPT-SatSun'!E10 -> 9745 | F10: ='UPT-Weekday'!F10+'UPT-SatSun'!F10 -> 25241 | G10: ='UPT-Weekday'!G10+'UPT-SatSun'!G10 -> 14761 | H10: ='UPT-Weekday'!H10+'UPT-SatSun'!H10 -> 4039 | I10: ='UPT-Weekday'!I10+'UPT-SatSun'!I10 -> 6033 | ... AL10: ='UPT-Weekday'!AL10+'UPT-SatSun'!AL10 -> 0 | AM10: =AVERAGE(B10:AL10) -> 12914.162
A11: 44440 | B11: ='UPT-Weekday'!B11+'UPT-SatSun'!B11 -> 16751 | C11: ='UPT-Weekday'!C11+'UPT-SatSun'!C11 -> 13134 | D11: ='UPT-Weekday'!D11+'UPT-SatSun'!D11 -> 19817 | E11: ='UPT-Weekday'!E11+'UPT-SatSun'!E11 -> 9943 | F11: ='UPT-Weekday'!F11+'UPT-SatSun'!F11 -> 26884 | G11: ='UPT-Weekday'!G11+'UPT-SatSun'!G11 -> 14583 | H11: ='UPT-Weekday'!H11+'UPT-SatSun'!H11 -> 4158 | I11: ='UPT-Weekday'!I11+'UPT-SatSun'!I11 -> 5949 | ... AL11: ='UPT-Weekday'!AL11+'UPT-SatSun'!AL11 -> 0 | AM11: =AVERAGE(B11:AL11) -> 13143.054
A12: 44470 | B12: ='UPT-Weekday'!B12+'UPT-SatSun'!B12 -> 17850 | C12: ='UPT-Weekday'!C12+'UPT-SatSun'!C12 -> 13519 | D12: ='UPT-Weekday'!D12+'UPT-SatSun'!D12 -> 20063 | E12: ='UPT-Weekday'!E12+'UPT-SatSun'!E12 -> 10011 | F12: ='UPT-Weekday'!F12+'UPT-SatSun'!F12 -> 26631 | G12: ='UPT-Weekday'!G12+'UPT-SatSun'!G12 -> 15341 | H12: ='UPT-Weekday'!H12+'UPT-SatSun'!H12 -> 4749 | I12: ='UPT-Weekday'!I12+'UPT-SatSun'!I12 -> 6684 | ... AL12: ='UPT-Weekday'!AL12+'UPT-SatSun'!AL12 -> 9 | AM12: =AVERAGE(B12:AL12) -> 13805.892
A13: 44501 | B13: ='UPT-Weekday'!B13+'UPT-SatSun'!B13 -> 16816 | C13: ='UPT-Weekday'!C13+'UPT-SatSun'!C13 -> 13695 | D13: ='UPT-Weekday'!D13+'UPT-SatSun'!D13 -> 18947 | E13: ='UPT-Weekday'!E13+'UPT-SatSun'!E13 -> 9818 | F13: ='UPT-Weekday'!F13+'UPT-SatSun'!F13 -> 24887 | G13: ='UPT-Weekday'!G13+'UPT-SatSun'!G13 -> 15461 | H13: ='UPT-Weekday'!H13+'UPT-SatSun'!H13 -> 5063 | I13: ='UPT-Weekday'!I13+'UPT-SatSun'!I13 -> 6412 | ... AL13: ='UPT-Weekday'!AL13+'UPT-SatSun'!AL13 -> 43 | AM13: =AVERAGE(B13:AL13) -> 13354.919
A14: 44531 | B14: ='UPT-Weekday'!B14+'UPT-SatSun'!B14 -> 15753 | C14: ='UPT-Weekday'!C14+'UPT-SatSun'!C14 -> 12841 | D14: ='UPT-Weekday'!D14+'UPT-SatSun'!D14 -> 16959 | E14: ='UPT-Weekday'!E14+'UPT-SatSun'!E14 -> 9071 | F14: ='UPT-Weekday'!F14+'UPT-SatSun'!F14 -> 22329 | G14: ='UPT-Weekday'!G14+'UPT-SatSun'!G14 -> 17066 | H14: ='UPT-Weekday'!H14+'UPT-SatSun'!H14 -> 5059 | I14: ='UPT-Weekday'!I14+'UPT-SatSun'!I14 -> 6438 | ... AL14: ='UPT-Weekday'!AL14+'UPT-SatSun'!AL14 -> 47 | AM14: =AVERAGE(B14:AL14) -> 12897.946
... A50: 45627 | B50: ='UPT-Weekday'!B50+'UPT-SatSun'!B50 -> 43680 | C50: ='UPT-Weekday'!C50+'UPT-SatSun'!C50 -> 20068 | D50: ='UPT-Weekday'!D50+'UPT-SatSun'!D50 -> 0 | E50: ='UPT-Weekday'!E50+'UPT-SatSun'!E50 -> 16394 | F50: ='UPT-Weekday'!F50+'UPT-SatSun'!F50 -> 32781 | G50: ='UPT-Weekday'!G50+'UPT-SatSun'!G50 -> 22126 | H50: ='UPT-Weekday'!H50+'UPT-SatSun'!H50 -> 6556 | I50: ='UPT-Weekday'!I50+'UPT-SatSun'!I50 -> 12773 | ... AL50: ='UPT-Weekday'!AL50+'UPT-SatSun'!AL50 -> 0 | AM50: =AVERAGE(B50:AL50) -> 18276.865

Sheet VRM-Weekday
A1: Route> | B1: 3 | C1: 4 | D1: 5 | E1: 6 | F1: 7 | G1: 8 | H1: 9 | I1: 14 | J1: 17 | K1: 18 | L1: 19 | M1: 21 | N1: 22 | O1: 23 | P1: 25 | Q1: 28 | R1: 29 | S1: 34 | T1: 41 | U1: 42 | V1: 50 | W1: 52 | X1: 55 | Y1: 56 | Z1: 64 | AA1: 70 | AB1: 71 | AC1: 72 | AD1: 75 | AE1: 76 | AF1: 77 | AG1: 79 | AH1: 84 | AI1: 86 | AJ1: 93 | AK1: 96 | AL1: 97
A2: Date
A3: 44197 | B3: 7515.07 | C3: 7777.65 | D3: 10752.67 | E3: 7905.14 | F3: 5796.52 | G3: 5979.3 | H3: 2462.02 | I3: 4937.34 | J3: 5407.78 | K3: 8186.91 | L3: 6674.89 | M3: 6319.4 | N3: 12985.36 | O3: 14809.74 | P3: 5447.3 | Q3: 3447.17 | R3: 4141.81 | S3: 7379.03 | T3: 0 | U3: 2404.26 | V3: 15534.21 | W3: 29449.62 | X3: 33400.29 | Y3: 34211.78 | Z3: 0 | AA3: 0 | AB3: 0 | AC3: 3375.16 | AE3: 5788.92 | AF3: 1506.51 | AH3: 0 | AI3: 0 | AJ3: 408.88 | AK3: 8932.85
A4: 44228 | B4: 7910.6 | C4: 8187 | D4: 11318.6 | E4: 8321.2 | F4: 6101.6 | G4: 6294 | H4: 2591.6 | I4: 5197.2 | J4: 5692.4 | K4: 8617.8 | L4: 7026.2 | M4: 6652 | N4: 13668.8 | O4: 15589.2 | P4: 5734 | Q4: 3628.6 | R4: 4359.8 | S4: 7767.4 | T4: 0 | U4: 2530.8 | V4: 16351.8 | W4: 30999.6 | X4: 35158.2 | Y4: 36012.4 | Z4: 0 | AA4: 0 | AB4: 0 | AC4: 3552.8 | AE4: 6093.6 | AF4: 1585.8 | AH4: 0 | AI4: 0 | AJ4: 430.4 | AK4: 9403
A5: 44256 | B5: 9097.19 | C5: 8982.69 | D5: 13016.39 | E5: 9569.38 | F5: 7016.84 | G5: 7246.92 | H5: 2980.34 | I5: 5976.78 | J5: 6546.26 | K5: 9910.47 | L5: 7836.95 | M5: 7649.8 | N5: 15804.8 | O5: 17927.58 | P5: 6594.1 | Q5: 4172.89 | R5: 5013.77 | S5: 8932.51 | T5: 0 | U5: 2910.42 | V5: 18906.27 | W5: 35649.54 | X5: 40670.07 | Y5: 41538.64 | Z5: 0 | AA5: 0 | AB5: 0 | AC5: 4085.72 | AE5: 7007.64 | AF5: 1823.67 | AH5: 0 | AI5: 0 | AJ5: 494.96 | AK5: 10813.45
A6: 44287 | B6: 10267.36 | C6: 11270.88 | D6: 16112.86 | E6: 11470.07 | F6: 10068.46 | G6: 6282.54 | H6: 2850.76 | I6: 6092.37 | J6: 6931.69 | K6: 9224.88 | L6: 8069.11 | M6: 5087.9 | N6: 15809.74 | O6: 24260.97 | P6: 4802.3 | Q6: 4151.51 | R6: 4894.78 | S6: 9037.64 | T6: 1583.85 | U6: 2902.08 | V6: 18416.73 | W6: 35052.96 | X6: 48859.95 | Y6: 45794.3 | Z6: 0 | AA6: 0 | AB6: 0 | AC6: 1243.48 | AE6: 6702.96 | AF6: 3792.33 | AH6: 8678.4 | AI6: 1437.75 | AJ6: 473.44 | AK6: 3291.05
A7: 44317 | B7: 9998.23 | C7: 11387.44 | D7: 16201.8 | E7: 11410.2 | F7: 10557.32 | G7: 5435.6 | H7: 2591.6 | I7: 5697.8 | J7: 6585.8 | K7: 8278.2 | L7: 7584.82 | M7: 3679.6 | N7: 14643.76 | O7: 25073 | P7: 3727.2 | Q7: 3842 | R7: 4491.8 | S7: 8425.4 | T7: 2111.8 | U7: 2688.4 | V7: 16848.45 | W7: 32270.8 | X7: 48600.63 | Y7: 44172.23 | Z7: 0 | AA7: 0 | AB7: 0 | AC7: 0 | AE7: 6093.6 | AF7: 4316.4 | AH7: 11571.2 | AI7: 1917 | AJ7: 430.4 | AK7: 0
A8: 44348 | B8: 10994.5 | C8: 12467.62 | D8: 17821.98 | E8: 12551.22 | F8: 11525.58 | G8: 5968.6 | H8: 2850.76 | I8: 6267.58 | J8: 7244.38 | K8: 9106.02 | L8: 8323.48 | M8: 4047.56 | N8: 16024.36 | O8: 27580.3 | P8: 4099.92 | Q8: 4226.2 | R8: 4940.98 | S8: 9267.94 | T8: 2322.98 | U8: 2957.24 | V8: 18377.92 | W8: 35497.88 | X8: 53292.36 | Y8: 48466 | Z8: 0 | AA8: 0 | AB8: 0 | AC8: 0 | AE8: 6702.96 | AF8: 4748.04 | AH8: 12728.32 | AI8: 2108.7 | AJ8: 473.44 | AK8: 0
A9: 44378 | B9: 10494.75 | C9: 11900.91 | D9: 17011.89 | E9: 11980.71 | F9: 11001.69 | G9: 5697.3 | H9: 2721.18 | I9: 5982.69 | J9: 6915.09 | K9: 8692.11 | L9: 7945.14 | M9: 3863.58 | N9: 15295.98 | O9: 26326.65 | P9: 3913.56 | Q9: 4034.1 | R9: 4716.39 | S9: 8846.67 | T9: 2217.39 | U9: 2822.82 | V9: 17542.56 | W9: 33884.34 | X9: 50869.98 | Y9: 46263 | Z9: 0 | AA9: 0 | AB9: 0 | AC9: 0 | AE9: 6398.28 | AF9: 4532.22 | AH9: 12149.76 | AI9: 2012.85 | AJ9: 451.92 | AK9: 0
A10: 44409 | B10: 10997.06 | C10: 12519.78 | D10: 17821.98 | E10: 12551.22 | F10: 11605.1 | G10: 5976.28 | H10: 2850.76 | I10: 6267.58 | J10: 7244.38 | K10: 9106.02 | L10: 8340.44 | M10: 4047.56 | N10: 16100.52 | O10: 27580.3 | P10: 4099.92 | Q10: 4226.2 | R10: 4940.98 | S10: 9267.94 | T10: 2322.98 | U10: 2957.24 | V10: 18515.84 | W10: 35497.88 | X10: 53441.16 | Y10: 48576.4 | Z10: 0 | AA10: 0 | AB10: 0 | AC10: 0 | AE10: 6702.96 | AF10: 4748.04 | AH10: 12728.32 | AI10: 2108.7 | AJ10: 473.44 | AK10: 0
A11: 44440 | B11: 10498.11 | C11: 11969.37 | D11: 17011.89 | E11: 11980.71 | F11: 11106.06 | G11: 5707.38 | H11: 2721.18 | I11: 5982.69 | J11: 6915.09 | K11: 8692.11 | L11: 7967.4 | M11: 3863.58 | N11: 15395.94 | O11: 26326.65 | P11: 3913.56 | Q11: 4034.1 | R11: 4716.39 | S11: 8846.67 | T11: 2217.39 | U11: 2822.82 | V11: 17723.58 | W11: 33884.34 | X11: 51065.28 | Y11: 46407.9 | Z11: 0 | AA11: 0 | AB11: 0 | AC11: 0 | AE11: 6398.28 | AF11: 4532.22 | AH11: 12149.76 | AI11: 2012.85 | AJ11: 451.92 | AK11: 0
A12: 44470 | B12: 11857.15 | C12: 12278.75 | D12: 20233.89 | E12: 13279.51 | F12: 12178.64 | G12: 6572.64 | H12: 4784.78 | I12: 5982.69 | J12: 6915.09 | K12: 8894.11 | L12: 7961.04 | M12: 3863.58 | N12: 15804.98 | O12: 28564.05 | P12: 3913.56 | Q12: 4034.1 | R12: 4716.39 | S12: 8846.67 | T12: 2217.39 | U12: 3184.42 | V12: 22909.74 | W12: 35891.54 | X12: 53350.08 | Y12: 46816.88 | Z12: 196.2 | AA12: 0 | AB12: 0 | AC12: 0 | AE12: 6443.08 | AF12: 4532.22 | AH12: 16488.96 | AI12: 3457.25 | AJ12: 632.72 | AK12: 0
A13: 44501 | B13: 11925.63 | C13: 12305.01 | D13: 20394.99 | E13: 13344.45 | F13: 12248.67 | G13: 6617.52 | H13: 4887.96 | I13: 5982.69 | J13: 6915.09 | K13: 8904.21 | L13: 7964.22 | M13: 3863.58 | N13: 15841.14 | O13: 28739.94 | P13: 3913.56 | Q13: 4034.1 | R13: 4716.39 | S13: 8846.67 | T13: 2217.39 | U13: 3202.5 | V13: 23197.23 | W13: 35991.9 | X13: 53518.11 | Y13: 46853.4 | Z13: 206.01 | AA13: 0 | AB13: 0 | AC13: 0 | AE13: 6445.32 | AF13: 4532.22 | AH13: 16705.92 | AI13: 3529.47 | AJ13: 641.76 | AK13: 0
A14: 44531 | B14: 11924.83 | C14: 12285.39 | D14: 20394.99 | E14: 13344.45 | F14: 12218.85 | G14: 6615.06 | H14: 4887.96 | I14: 5982.69 | J14: 6915.09 | K14: 8904.21 | L14: 7957.86 | M14: 3863.58 | N14: 15813.4 | O14: 28623.54 | P14: 3913.56 | Q14: 4034.1 | R14: 4716.39 | S14: 8846.67 | T14: 2217.39 | U14: 3202.5 | V14: 23151.37 | W14: 35991.9 | X14: 53426.3 | Y14: 46827.22 | Z14: 206.01 | AA14: 0 | AB14: 0 | AC14: 0 | AE14: 6445.32 | AF14: 4532.22 | AH14: 16705.92 | AI14: 3529.47 | AJ14: 641.76 | AK14: 0
... A17: 44621 | B17: 13061.13 | C17: 13469.12 | D17: 22337.37 | E17: 14615.35 | F17: 12967.71 | G17: 7009.38 | H17: 5353.48 | I17: 6552.47 | J17: 7336.31 | K17: 9752.23 | L17: 8720.9 | M17: 4231.54 | N17: 17337.73 | O17: 31433.63 | P17: 4286.28 | Q17: 4418.3 | R17: 5165.57 | S17: 9689.21 | T17: 2428.57 | U17: 3507.5 | V17: 25391.85 | W17: 39419.7 | X17: 58581.05 | Y17: 51307.29 | Z17: 225.63 | AA17: 0 | AB17: 0 | AC17: 0 | AE17: 7059.16 | AF17: 4963.86 | AH17: 18296.96 | AI17: 3865.61 | AJ17: 702.88 | AK17: 0
A18: 44652 | B18: 32847.95 | C18: 12176.41 | D18: 971.19 | E18: 17331.25 | F18: 12517.22 | G18: 6614.17 | H18: 4897.56 | I18: 7830.69 | J18: 10050.17 | K18: 8904.21 | L18: 11053.14 | M18: 183.98 | N18: 16143.61 | O18: 28809.54 | P18: 186.36 | Q18: 5183.5 | R18: 5773.39 | S18: 8846.67 | T18: 2217.39 | U18: 4106.3 | V18: 23561 | W18: 36527.9 | X18: 54098.94 | Y18: 47343.09 | Z18: 206.01 | AA18: 0 | AB18: 0 | AC18: 0 | AD18: 3727.2 | AE18: 6066.32 | AF18: 9770.82 | AG18: 9417.67 | AH18: 16716.72 | AI18: 3540.87 | AJ18: 641.76 | AK18: 0
A19: 44682 | B19: 33894.57 | C19: 12166.63 | D19: 0 | E19: 17530.59 | F19: 12544.69 | G19: 6626.27 | H19: 4898.04 | I19: 7923.09 | J19: 10217.76 | K19: 8904.21 | L19: 11206.42 | M19: 0 | N19: 16156.73 | O19: 28810.11 | P19: 0 | Q19: 5240.97 | R19: 5826.24 | S19: 8846.67 | T19: 2217.39 | U19: 4151.49 | V19: 23591.56 | W19: 36554.7 | X19: 54133.81 | Y19: 47374.09 | Z19: 206.01 | AA19: 0 | AB19: 0 | AC19: 0 | AD19: 3913.56 | AE19: 6047.37 | AF19: 10032.75 | AG19: 9886.72 | AH19: 16717.26 | AI19: 3541.44 | AJ19: 641.76 | AK19: 0
A20: 44713 | B20: 35504.7 | C20: 12686.08 | D20: 0 | E20: 18365.38 | F20: 13036.76 | G20: 6930 | H20: 5131.28 | I20: 8300.38 | J20: 10704.32 | K20: 9328.22 | L20: 11718.96 | M20: 0 | N20: 16826.92 | O20: 30182.02 | P20: 0 | Q20: 5490.54 | R20: 6103.68 | S20: 9267.94 | T20: 2322.98 | U20: 4349.18 | V20: 24524.06 | W20: 38295.4 | X20: 56358.72 | Y20: 49519.58 | Z20: 215.82 | AA20: 0 | AB20: 0 | AC20: 0 | AD20: 4099.92 | AE20: 6335.34 | AF20: 10510.5 | AG20: 10319.1 | AH20: 17513.32 | AI20: 3710.08 | AJ20: 672.32 | AK20: 0
A21: 44743 | B21: 26989.06 | C21: 11943.96 | D21: 0 | E21: 12067.91 | F21: 10750.79 | G21: 5500.67 | H21: 2719.14 | I21: 5971.9 | J21: 6699.16 | K21: 8717.6 | L21: 7930.43 | M21: 0 | N21: 15205.86 | O21: 27783.37 | P21: 0 | Q21: 4041.52 | R21: 4721.46 | S21: 8847.65 | T21: 2215.07 | U21: 2822.62 | V21: 17556 | W21: 33814.72 | X21: 50871.61 | Y21: 46036.19 | Z21: 196.2 | AA21: 0 | AB21: 0 | AC21: 0 | AD21: 3917.34 | AE21: 6398.64 | AF21: 8061.86 | AG21: 9381 | AH21: 12110.7 | AI21: 2012.83 | AJ21: 448.64 | AK21: 0
A22: 44774 | B22: 28279.99 | C22: 12564.82 | D22: 0 | E22: 12648.96 | F22: 11342.4 | G22: 5770.35 | H22: 2848.62 | I22: 6256.51 | J22: 7018.17 | K22: 9132.65 | L22: 8325.44 | M22: 0 | N22: 16005.63 | O22: 29147.06 | P22: 0 | Q22: 4233.97 | R22: 4946.29 | S22: 9268.97 | T22: 2320.55 | U22: 2957.03 | V22: 18526.48 | W22: 35424.94 | X22: 53457.62 | Y22: 48336.47 | Z22: 225.6 | AA22: 0 | AB22: 0 | AC22: 0 | AD22: 4103.88 | AE22: 6703.34 | AF22: 8519.78 | AG22: 10823 | AH22: 12687.37 | AI22: 2108.68 | AJ22: 470.06 | AK22: 0
A23: 44805 | B23: 26995.34 | C23: 12009.08 | D23: 0 | E23: 12074.01 | F23: 10850.37 | G23: 5510.35 | H23: 2719.14 | I23: 5972.9 | J23: 6699.16 | K23: 8717.27 | L23: 7952.14 | M23: 0 | N23: 15299.38 | O23: 27934.95 | P23: 0 | Q23: 4041.52 | R23: 4721.46 | S23: 8847.65 | T23: 2215.07 | U23: 2822.62 | V23: 17724.1 | W23: 33814.72 | X23: 51076.05 | Y23: 46171.99 | Z23: 206 | AA23: 0 | AB23: 0 | AC23: 0 | AD23: 3917.34 | AE23: 6398.64 | AF23: 8372.78 | AG23: 988.7 | AH23: 12110.57 | AI23: 2012.83 | AJ23: 448.69 | AK23: 0
A24: 44835 | B24: 32041.8 | C24: 12315.83 | D24: 0 | E24: 13293.38 | F24: 11799.43 | G24: 6345.64 | H24: 4781.18 | I24: 5973.11 | J24: 6699.16 | K24: 8919.17 | L24: 7945.63 | M24: 0 | N24: 15703.74 | O24: 27953.07 | P24: 0 | Q24: 4041.52 | R24: 4721.46 | S24: 8847.65 | T24: 2215.07 | U24: 3184.14 | V24: 22900.64 | W24: 35819.84 | X24: 53337.02 | Y24: 46580.66 | Z24: 196.18 | AA24: 0 | AB24: 0 | AC24: 0 | AD24: 3917.29 | AE24: 6443.08 | AF24: 8372.78 | AG24: 8862.6 | AH24: 16437.95 | AI24: 3455.04 | AJ24: 627.99 | AK24: 0
A25: 44866 | B25: 32294.85 | C25: 12345.17 | D25: 0 | E25: 13354.43 | F25: 11863.53 | G25: 6389.49 | H25: 4884.28 | I25: 5973.12 | J25: 6699.16 | K25: 8929.37 | L25: 7949.93 | M25: 0 | N25: 15739.98 | O25: 28067.91 | P25: 0 | Q25: 4041.52 | R25: 4721.46 | S25: 8847.65 | T25: 2215.07 | U25: 3202.22 | V25: 23195.93 | W25: 35920.47 | X25: 53520.89 | Y25: 46621.92 | Z25: 205.99 | AA25: 0 | AB25: 0 | AC25: 0 | AD25: 3917.29 | AE25: 6445.31 | AF25: 8372.78 | AG25: 8868.4 | AH25: 16653.45 | AI25: 3528.02 | AJ25: 636.96 | AK25: 0
A26: 44896 | B26: 32294.34 | C26: 12323.46 | D26: 0 | E26: 13354.57 | F26: 11820.98 | G26: 6388.04 | H26: 4884.28 | I26: 5973.12 | J26: 6699.16 | K26: 8929.53 | L26: 7943.34 | M26: 0 | N26: 15702.82 | O26: 28172.62 | P26: 0 | Q26: 4041.52 | R26: 4721.46 | S26: 8847.65 | T26: 2215.07 | U26: 3202.22 | V26: 23160.39 | W26: 35921.06 | X26: 53435.64 | Y26: 46601.86 | Z26: 205.99 | AA26: 0 | AB26: 0 | AC26: 0 | AD26: 3917.29 | AE26: 6445.31 | AF26: 8372.78 | AG26: 8850.1 | AH26: 16652.04 | AI26: 3529.43 | AJ26: 636.96 | AK26: 0
A27: 44927 | B27: 32295.42 | C27: 11372.22 | D27: 0 | E27: 16709.91 | F27: 11952.31 | G27: 6296.89 | H27: 5022.33 | I27: 7542.89 | J27: 9726.13 | K27: 8483.29 | L27: 10651.45 | M27: 0 | N27: 15313.02 | O27: 27029.76 | P27: 0 | Q27: 4987.75 | R27: 5681.91 | S27: 8426.33 | T27: 2128.21 | U27: 3946.27 | V27: 22451.68 | W27: 34822.24 | X27: 51984.98 | Y27: 44884.37 | Z27: 196.15 | AA27: 0 | AB27: 0 | AC27: 0 | AD27: 3730.9 | AE27: 5757.1 | AF27: 8927.86 | AG27: 8440.81 | AH27: 15870.83 | AI27: 3373.05 | AJ27: 606.62 | AK27: 0
A28: 44958 | B28: 32313.73 | C28: 11381.99 | D28: 0 | E28: 16709.91 | F28: 11968.21 | G28: 6298.34 | H28: 4963.83 | I28: 7543.89 | J28: 9730.16 | K28: 8483.29 | L28: 10654.71 | M28: 0 | N28: 15297.18 | O28: 27029.76 | P28: 0 | Q28: 4866.94 | R28: 5681.91 | S28: 8426.33 | T28: 2109.54 | U28: 3955.69 | V28: 22481.37 | W28: 34822.33 | X28: 52034.14 | Y28: 44899.74 | Z28: 196.14 | AA28: 0 | AB28: 0 | AC28: 0 | AD28: 3730.9 | AE28: 5756.87 | AF28: 8927.86 | AG28: 8446.63 | AH28: 15870.83 | AI28: 3373.05 | AJ28: 697.62 | AK28: 0
A29: 44986 | B29: 37160.13 | C29: 13074.57 | D29: 0 | E29: 19216.4 | F29: 13737.73 | G29: 7241.22 | H29: 5708.41 | I29: 8675.47 | J29: 11189.68 | K29: 9755.79 | L29: 12248.74 | M29: 0 | N29: 17569.25 | O29: 31084.23 | P29: 0 | Q29: 5596.98 | R29: 6534.2 | S29: 9690.28 | T29: 2425.97 | U29: 4549.04 | V29: 25813.99 | W29: 40045.67 | X29: 59770 | Y29: 51614.88 | Z29: 225.57 | AA29: 0 | AB29: 0 | AC29: 0 | AD29: 4290.54 | AE29: 6620.4 | AF29: 10267.04 | AG29: 9697.53 | AH29: 18251.46 | AI29: 3879.01 | AJ29: 636.96 | AK29: 0
... A50: 45627 | B50: 33593.43 | C50: 12003.5 | D50: 0 | E50: 18606 | F50: 14111.24 | G50: 7339.93 | H50: 5087.3 | I50: 7544.41 | J50: 9729.73 | K50: 8538.7 | L50: 11201.48 | M50: 0 | N50: 15797.44 | O50: 27831.42 | P50: 0 | Q50: 5108.64 | R50: 5572.3 | S50: 8120.33 | T50: 2147.11 | U50: 4411.96 | V50: 23140.65 | W50: 35891.53 | X50: 53053.77 | Y50: 45836.85 | Z50: 196.16 | AA50: 4248.5 | AB50: 10087 | AC50: 0 | AD50: 4878.87 | AE50: 5895.43 | AF50: 11168.45 | AG50: 8428.31 | AH50: 16482.19 | AI50: 3373.05 | AJ50: 607.97 | AK50: 0

Sheet VRM-SatSun
B1: SAT/SUN COMBINED
A3: Route> | B3: 3 | C3: 4 | D3: 5 | E3: 6 | F3: 7 | G3: 8 | H3: 9 | I3: 14 | J3: 17 | K3: 18 | L3: 19 | M3: 21 | N3: 22 | O3: 23 | P3: 25 | Q3: 28 | R3: 29 | S3: 34 | T3: 41 | U3: 42 | V3: 50 | W3: 52 | X3: 55 | Y3: 56 | Z3: 64 | AA3: 70 | AB3: 71 | AC3: 72 | AD3: 75 | AE3: 76 | AF3: 77 | AG3: 79 | AH3: 84 | AI3: 86 | AJ3: 93 | AK3: 96 | AL3: 97 | AM3: AVERAGE
A4: Date
A5: 44197 | B5: 4293.96 | C5: 4813.5 | D5: 6713.76 | E5: 2111.58 | F5: 3219.42 | G5: 2148.66 | H5: 0 | I5: 2786.04 | J5: 2779.86 | K5: 3837 | L5: 3891.48 | M5: 1995.6 | N5: 5287.2 | O5: 5102.94 | P5: 3354.42 | Q5: 2113.08 | R5: 2536.62 | S5: 4160.4 | T5: 0 | U5: 1459.14 | V5: 6611.82 | W5: 11173.56 | X5: 14565.3 | Y5: 13217.94 | Z5: 0 | AA5: 0 | AB5: 0 | AC5: 1065.84 | AD5: 0 | AE5: 1411.44 | AF5: 475.74 | AG5: 0 | AH5: 0 | AI5: 0 | AJ5: 0 | AK5: 0 | AL5: 0
A6: 44228 | B6: 2862.64 | C6: 3209 | D6: 4475.84 | E6: 1407.72 | F6: 2146.28 | G6: 1432.44 | H6: 0 | I6: 1857.36 | J6: 1853.24 | K6: 2558 | L6: 2594.32 | M6: 1330.4 | N6: 3524.8 | O6: 3401.96 | P6: 2236.28 | Q6: 1408.72 | R6: 1691.08 | S6: 2773.6 | T6: 0 | U6: 972.76 | V6: 4407.88 | W6: 7449.04 | X6: 9710.2 | Y6: 8811.96 | Z6: 0 | AA6: 0 | AB6: 0 | AC6: 710.56 | AD6: 0 | AE6: 940.96 | AF6: 317.16 | AG6: 0 | AH6: 0 | AI6: 0 | AJ6: 0 | AK6: 0 | AL6: 0
A7: 44256 | B7: 2862.64 | C7: 3209 | D7: 4475.84 | E7: 1407.72 | F7: 2146.28 | G7: 1432.44 | H7: 0 | I7: 1857.36 | J7: 1853.24 | K7: 2558 | L7: 2594.32 | M7: 1330.4 | N7: 3524.8 | O7: 3401.96 | P7: 2236.28 | Q7: 1408.72 | R7: 1691.08 | S7: 2773.6 | T7: 0 | U7: 972.76 | V7: 4407.88 | W7: 7449.04 | X7: 9710.2 | Y7: 8811.96 | Z7: 0 | AA7: 0 | AB7: 0 | AC7: 710.56 | AD7: 0 | AE7: 940.96 | AF7: 317.16 | AG7: 0 | AH7: 0 | AI7: 0 | AJ7: 0 | AK7: 0 | AL7: 0
A8: 44287 | B8: 2862.64 | C8: 3209 | D8: 4475.84 | E8: 2463.51 | F8: 2146.28 | G8: 1432.44 | H8: 0 | I8: 1857.36 | J8: 1853.24 | K8: 2558 | L8: 2594.32 | M8: 948.24 | N8: 3524.8 | O8: 4762.4 | P8: 1218.49 | Q8: 1408.72 | R8: 1691.08 | S8: 3113.78 | T8: 0 | U8: 972.76 | V8: 4407.88 | W8: 7446.1 | X8: 9697.33 | Y8: 8811.96 | Z8: 0 | AA8: 0 | AB8: 0 | AC8: 355.28 | AD8: 0 | AE8: 940.96 | AF8: 466.9 | AG8: 0 | AH8: 0 | AI8: 0 | AJ8: 0 | AK8: 0 | AL8: 0
A9: 44317 | B9: 3921.16 | C9: 4404.15 | D9: 6147.83 | E9: 3871.23 | F9: 2945.53 | G9: 1964.18 | H9: 0 | I9: 2526.18 | J9: 2495.24 | K9: 3517.25 | L9: 3553.68 | M9: 707.6 | N9: 4805.1 | O9: 7665.05 | P9: 931.8 | Q9: 1931.65 | R9: 2318.63 | S9: 4485.29 | T9: 0 | U9: 1332.6 | V9: 5883.1 | W9: 10215.83 | X9: 13296.76 | Y9: 12092.5 | Z9: 0 | AA9: 0 | AB9: 0 | AC9: 0 | AD9: 0 | AE9: 1293.82 | AF9: 770.8 | AG9: 0 | AH9: 0 | AI9: 0 | AJ9: 0 | AK9: 0 | AL9: 0
A10: 44348 | B10: 2862.64 | C10: 3209 | D10: 4475.84 | E10: 2815.44 | F10: 2146.28 | G10: 1432.44 | H10: 0 | I10: 1857.36 | J10: 1853.24 | K10: 2558 | L10: 2594.32 | M10: 566.08 | N10: 3524.8 | O10: 5583.6 | P10: 745.44 | Q10: 1408.72 | R10: 1691.08 | S10: 3271.04 | T10: 0 | U10: 972.76 | V10: 4407.88 | W10: 7444.32 | X10: 9689.52 | Y10: 8811.96 | Z10: 0 | AA10: 0 | AB10: 0 | AC10: 0 | AD10: 0 | AE10: 940.96 | AF10: 616.64 | AG10: 0 | AH10: 0 | AI10: 0 | AJ10: 0 | AK10: 0 | AL10: 0
A11: 44378 | B11: 3578.3 | C11: 4011.25 | D11: 5594.8 | E11: 3519.3 | F11: 2682.85 | G11: 1790.55 | H11: 0 | I11: 2321.7 | J11: 2316.55 | K11: 3197.5 | L11: 3242.9 | M11: 707.6 | N11: 4406 | O11: 6979.5 | P11: 931.8 | Q11: 1760.9 | R11: 2113.85 | S11: 4088.8 | T11: 0 | U11: 1215.95 | V11: 5509.85 | W11: 9305.4 | X11: 12111.9 | Y11: 11014.95 | Z11: 0 | AA11: 0 | AB11: 0 | AC11: 0 | AD11: 0 | AE11: 1176.2 | AF11: 770.8 | AG11: 0 | AH11: 0 | AI11: 0 | AJ11: 0 | AK11: 0 | AL11: 0
A12: 44409 | B12: 3205.5 | C12: 3601.9 | D12: 5028.87 | E12: 3167.37 | F12: 2408.96 | G12: 1606.07 | H12: 0 | I12: 2061.84 | J12: 2031.93 | K12: 2877.75 | L12: 2905.1 | M12: 566.08 | N12: 3923.9 | O12: 6269.15 | P12: 745.44 | Q12: 1579.47 | R12: 1895.86 | S12: 3667.53 | T12: 0 | U12: 1089.41 | V12: 4781.13 | W12: 8354.75 | X12: 10874.38 | Y12: 9889.51 | Z12: 0 | AA12: 0 | AB12: 0 | AC12: 0 | AD12: 0 | AE12: 1058.58 | AF12: 616.64 | AG12: 0 | AH12: 0 | AI12: 0 | AJ12: 0 | AK12: 0 | AL12: 0
A13: 44440 | B13: 3205.5 | C13: 3601.9 | D13: 5028.87 | E13: 3167.37 | F13: 2408.96 | G13: 1606.07 | H13: 0 | I13: 2061.84 | J13: 2031.93 | K13: 2877.75 | L13: 2905.1 | M13: 566.08 | N13: 3923.9 | O13: 6269.15 | P13: 745.44 | Q13: 1579.47 | R13: 1895.86 | S13: 3667.53 | T13: 0 | U13: 1089.41 | V13: 4781.13 | W13: 8354.75 | X13: 10874.38 | Y13: 9889.51 | Z13: 0 | AA13: 0 | AB13: 0 | AC13: 0 | AD13: 0 | AE13: 1058.58 | AF13: 616.64 | AG13: 0 | AH13: 0 | AI13: 0 | AJ13: 0 | AK13: 0 | AL13: 0
A14: 44470 | B14: 3764.54 | C14: 4342.86 | D14: 6309.82 | E14: 3609.66 | F14: 2864.82 | G14: 2009.57 | H14: 0 | I14: 2861.15 | J14: 2517.52 | K14: 3431.87 | L14: 3522.47 | M14: 707.6 | N14: 4681.24 | O14: 8003.47 | P14: 931.8 | Q14: 1943.05 | R14: 2232.74 | S14: 4187.96 | T14: 0 | U14: 1373.28 | V14: 5797.2 | W14: 10245.92 | X14: 13092.48 | Y14: 11541.76 | Z14: 0 | AA14: 0 | AB14: 0 | AC14: 0 | AD14: 0 | AE14: 1377.8 | AF14: 770.8 | AG14: 0 | AH14: 0 | AI14: 0 | AJ14: 0 | AK14: 0 | AL14: 0
A15: 44501 | B15: 3391.74 | C15: 3933.51 | D15: 5743.89 | E15: 3257.73 | F15: 2590.93 | G15: 1825.09 | H15: 0 | I15: 2601.29 | J15: 2232.9 | K15: 3112.12 | L15: 3184.67 | M15: 566.08 | N15: 4199.14 | O15: 7293.12 | P15: 745.44 | Q15: 1761.62 | R15: 2014.75 | S15: 3766.69 | T15: 0 | U15: 1246.74 | V15: 5068.48 | W15: 9295.27 | X15: 11854.96 | Y15: 10416.32 | Z15: 0 | AA15: 0 | AB15: 0 | AC15: 0 | AD15: 0 | AE15: 1260.18 | AF15: 616.64 | AG15: 0 | AH15: 0 | AI15: 0 | AJ15: 0 | AK15: 0 | AL15: 0
A16: 44531 | B16: 3755.64 | C16: 4359.3 | D16: 6382.1 | E16: 3619.7 | F16: 2871.06 | G16: 2020.42 | H16: 0 | I16: 2886.18 | J16: 2433.92 | K16: 3449.36 | L16: 3535.98 | M16: 566.08 | N16: 4621 | O16: 8076.84 | P16: 745.44 | Q16: 1953.72 | R16: 2232.74 | S16: 4163.18 | T16: 0 | U16: 1381.32 | V16: 5469.08 | W16: 10305.38 | X16: 13135.84 | Y16: 11541.76 | Z16: 0 | AA16: 0 | AB16: 0 | AC16: 0 | AD16: 0 | AE16: 1377.8 | AF16: 616.64 | AG16: 0 | AH16: 0 | AI16: 0 | AJ16: 0 | AK16: 0 | AL16: 0
... A52: 45627 | B52: 12013.89 | C52: 4956.93 | D52: 0 | E52: 6227.32 | F52: 4447.18 | G52: 3304.83 | H52: 0 | I52: 3246.81 | J52: 3162.17 | K52: 4948.35 | L52: 4152.47 | M52: 0 | N52: 5583.16 | O52: 9483.33 | P52: 0 | Q52: 2178.87 | R52: 2474.25 | S52: 4476.49 | T52: 0 | U52: 1853.6 | V52: 8700.05 | W52: 12135.6 | X52: 17181.34 | Y52: 13479.13 | Z52: 0 | AA52: 0 | AB52: 0 | AC52: 0 | AD52: 2683.38 | AE52: 2264.83 | AF52: 7014.75 | AG52: 1034.5 | AH52: 0 | AI52: 0 | AJ52: 0 | AK52: 0 | AL52: 0
A57: SATURDAY
A58: 44197 | B58: 2236.8 | C58: 2456.1 | D58: 3395.58 | E58: 2111.58 | F58: 1643.34 | G58: 1106.88 | H58: 0 | I58: 1559.16 | J58: 1707.72 | K58: 1918.5 | L58: 2026.8 | M58: 1995.6 | N58: 2892.6 | O58: 2607.36 | P58: 1720.2 | Q58: 1088.58 | R58: 1307.94 | S58: 2330.22 | T58: 0 | U58: 759.24 | V58: 4372.32 | W58: 5707.5 | X58: 7440.96 | Y58: 6752.64 | Z58: 0 | AA58: 0 | AB58: 0 | AC58: 1065.84 | AD58: 0 | AE58: 705.72 | AF58: 475.74 | AG58: 0 | AH58: 0 | AI58: 0 | AJ58: 0 | AK58: 0 | AL58: 0
A59: 44228 | B59: 1491.2 | C59: 1637.4 | D59: 2263.72 | E59: 1407.72 | F59: 1095.56 | G59: 737.92 | H59: 0 | I59: 1039.44 | J59: 1138.48 | K59: 1279 | L59: 1351.2 | M59: 1330.4 | N59: 1928.4 | O59: 1738.24 | P59: 1146.8 | Q59: 725.72 | R59: 871.96 | S59: 1553.48 | T59: 0 | U59: 506.16 | V59: 2914.88 | W59: 3805 | X59: 4960.64 | Y59: 4501.76 | Z59: 0 | AA59: 0 | AB59: 0 | AC59: 710.56 | AD59: 0 | AE59: 470.48 | AF59: 317.16 | AG59: 0 | AH59: 0 | AI59: 0 | AJ59: 0 | AK59: 0 | AL59: 0
A60: 44256 | B60: 1491.2 | C60: 1637.4 | D60: 2263.72 | E60: 1407.72 | F60: 1095.56 | G60: 737.92 | H60: 0 | I60: 1039.44 | J60: 1138.48 | K60: 1279 | L60: 1351.2 | M60: 1330.4 | N60: 1928.4 | O60: 1738.24 | P60: 1146.8 | Q60: 725.72 | R60: 871.96 | S60: 1553.48 | T60: 0 | U60: 506.16 | V60: 2914.88 | W60: 3805 | X60: 4960.64 | Y60: 4501.76 | Z60: 0 | AA60: 0 | AB60: 0 | AC60: 710.56 | AD60: 0 | AE60: 470.48 | AF60: 317.16 | AG60: 0 | AH60: 0 | AI60: 0 | AJ60: 0 | AK60: 0 | AL60: 0
